2024-07-03 20:58:38 INFO The form has been created
2024-07-03 20:58:44 INFO The form has been created
2024-07-03 20:58:44 INFO The form has been submitted and validated
2024-07-03 20:58:44 INFO The user has logged in
2024-07-03 20:58:49 INFO The form has been created
2024-07-04 12:57:22 ERROR OSError: write error
2024-07-04 12:57:36 INFO The form has been created
2024-07-04 19:26:31 INFO The form has been created
2024-07-04 19:31:04 INFO The form has been created
2024-07-04 19:31:07 INFO The form has been created
2024-07-04 19:31:15 INFO The form has been created
2024-07-04 19:31:29 INFO The form has been created
2024-07-04 19:31:40 INFO The form has been created
2024-07-04 19:34:27 INFO The form has been created
2024-07-04 19:34:36 INFO The form has been created
2024-07-04 19:34:45 INFO The form has been created
2024-07-04 19:34:56 INFO The form has been created
2024-07-04 19:35:17 INFO The form has been created
2024-07-04 19:37:12 INFO The form has been created
2024-07-04 19:37:15 INFO The form has been created
2024-07-04 19:37:27 INFO The form has been created
2024-07-04 19:38:28 INFO The form has been created
2024-07-04 19:39:20 INFO The form has been created
2024-07-04 19:39:33 INFO The form has been created
2024-07-04 19:39:33 INFO The form has been submitted and validated
2024-07-04 19:39:33 INFO The user has logged in
2024-07-04 19:39:40 INFO The form has been created
2024-07-04 19:40:01 INFO The form has been created
2024-07-04 19:41:15 INFO The form has been created
2024-07-04 19:41:34 INFO The form has been created
2024-07-04 19:41:36 INFO The form has been created
2024-07-04 19:42:15 INFO The form has been created
2024-07-04 19:42:19 INFO The form has been created
2024-07-04 19:43:26 INFO The form has been created
2024-07-04 19:43:48 INFO The form has been created
2024-07-04 19:45:09 INFO The form has been created
2024-07-04 19:45:31 ERROR Exception on /auth/register [POST]
Traceback (most recent call last):
  File "/home/Flasheeta/.virtualenvs/myenv/lib/python3.8/site-packages/sqlalchemy/engine/base.py", line 1967, in _exec_single_context
    self.dialect.do_execute(
  File "/home/Flasheeta/.virtualenvs/myenv/lib/python3.8/site-packages/sqlalchemy/engine/default.py", line 924, in do_execute
    cursor.execute(statement, parameters)
  File "/home/Flasheeta/.virtualenvs/myenv/lib/python3.8/site-packages/MySQLdb/cursors.py", line 179, in execute
    res = self._query(mogrified_query)
  File "/home/Flasheeta/.virtualenvs/myenv/lib/python3.8/site-packages/MySQLdb/cursors.py", line 330, in _query
    db.query(q)
  File "/home/Flasheeta/.virtualenvs/myenv/lib/python3.8/site-packages/MySQLdb/connections.py", line 261, in query
    _mysql.connection.query(self, query)
MySQLdb.OperationalError: (4031, 'The client was disconnected by the server because of inactivity. See wait_timeout and interactive_timeout for configuring this behavior.')

The above exception was the direct cause of the following exception:

Traceback (most recent call last):
  File "/home/Flasheeta/.virtualenvs/myenv/lib/python3.8/site-packages/flask/app.py", line 1473, in wsgi_app
    response = self.full_dispatch_request()
  File "/home/Flasheeta/.virtualenvs/myenv/lib/python3.8/site-packages/flask/app.py", line 882, in full_dispatch_request
    rv = self.handle_user_exception(e)
  File "/home/Flasheeta/.virtualenvs/myenv/lib/python3.8/site-packages/flask/app.py", line 880, in full_dispatch_request
    rv = self.dispatch_request()
  File "/home/Flasheeta/.virtualenvs/myenv/lib/python3.8/site-packages/flask/app.py", line 865, in dispatch_request
    return self.ensure_sync(self.view_functions[rule.endpoint])(**view_args)  # type: ignore[no-any-return]
  File "/home/Flasheeta/Flasheeta/app/web_routes/auth_routes.py", line 25, in register
    old_user = User.query.filter_by(name=username).first()
  File "/home/Flasheeta/.virtualenvs/myenv/lib/python3.8/site-packages/sqlalchemy/orm/query.py", line 2728, in first
    return self.limit(1)._iter().first()  # type: ignore
  File "/home/Flasheeta/.virtualenvs/myenv/lib/python3.8/site-packages/sqlalchemy/orm/query.py", line 2827, in _iter
    result: Union[ScalarResult[_T], Result[_T]] = self.session.execute(
  File "/home/Flasheeta/.virtualenvs/myenv/lib/python3.8/site-packages/sqlalchemy/orm/session.py", line 2351, in execute
    return self._execute_internal(
  File "/home/Flasheeta/.virtualenvs/myenv/lib/python3.8/site-packages/sqlalchemy/orm/session.py", line 2236, in _execute_internal
    result: Result[Any] = compile_state_cls.orm_execute_statement(
  File "/home/Flasheeta/.virtualenvs/myenv/lib/python3.8/site-packages/sqlalchemy/orm/context.py", line 293, in orm_execute_statement
    result = conn.execute(
  File "/home/Flasheeta/.virtualenvs/myenv/lib/python3.8/site-packages/sqlalchemy/engine/base.py", line 1418, in execute
    return meth(
  File "/home/Flasheeta/.virtualenvs/myenv/lib/python3.8/site-packages/sqlalchemy/sql/elements.py", line 515, in _execute_on_connection
    return connection._execute_clauseelement(
  File "/home/Flasheeta/.virtualenvs/myenv/lib/python3.8/site-packages/sqlalchemy/engine/base.py", line 1640, in _execute_clauseelement
    ret = self._execute_context(
  File "/home/Flasheeta/.virtualenvs/myenv/lib/python3.8/site-packages/sqlalchemy/engine/base.py", line 1846, in _execute_context
    return self._exec_single_context(
  File "/home/Flasheeta/.virtualenvs/myenv/lib/python3.8/site-packages/sqlalchemy/engine/base.py", line 1986, in _exec_single_context
    self._handle_dbapi_exception(
  File "/home/Flasheeta/.virtualenvs/myenv/lib/python3.8/site-packages/sqlalchemy/engine/base.py", line 2353, in _handle_dbapi_exception
    raise sqlalchemy_exception.with_traceback(exc_info[2]) from e
  File "/home/Flasheeta/.virtualenvs/myenv/lib/python3.8/site-packages/sqlalchemy/engine/base.py", line 1967, in _exec_single_context
    self.dialect.do_execute(
  File "/home/Flasheeta/.virtualenvs/myenv/lib/python3.8/site-packages/sqlalchemy/engine/default.py", line 924, in do_execute
    cursor.execute(statement, parameters)
  File "/home/Flasheeta/.virtualenvs/myenv/lib/python3.8/site-packages/MySQLdb/cursors.py", line 179, in execute
    res = self._query(mogrified_query)
  File "/home/Flasheeta/.virtualenvs/myenv/lib/python3.8/site-packages/MySQLdb/cursors.py", line 330, in _query
    db.query(q)
  File "/home/Flasheeta/.virtualenvs/myenv/lib/python3.8/site-packages/MySQLdb/connections.py", line 261, in query
    _mysql.connection.query(self, query)
sqlalchemy.exc.OperationalError: (MySQLdb.OperationalError) (4031, 'The client was disconnected by the server because of inactivity. See wait_timeout and interactive_timeout for configuring this behavior.')
[SQL: SELECT users.name AS users_name, users.id AS users_id, users.created_at AS users_created_at, users.updated_at AS users_updated_at 
FROM users 
WHERE users.name = %s 
 LIMIT %s]
[parameters: ('Ahmed elsaid', 1)]
(Background on this error at: https://sqlalche.me/e/20/e3q8)
2024-07-04 19:46:41 INFO The form has been created
2024-07-04 19:47:58 INFO The form has been created
2024-07-04 19:48:05 INFO The form has been created
2024-07-04 19:48:05 INFO The form has been submitted and validated
2024-07-04 19:48:05 INFO The user has logged in
2024-07-04 19:48:50 INFO The form has been created
2024-07-04 19:48:50 INFO The form has been submitted and validated
2024-07-04 19:48:50 INFO The user has logged in
2024-07-04 19:49:15 INFO The form has been created
2024-07-04 19:52:44 INFO The form has been created
2024-07-04 19:54:14 INFO The form has been created
2024-07-04 20:35:33 INFO The form has been created
2024-07-04 20:35:38 INFO The form has been created
2024-07-04 20:55:02 INFO The form has been created
2024-07-04 20:59:26 INFO The form has been created
2024-07-04 21:17:11 INFO The form has been created
2024-07-04 21:17:24 INFO The form has been created
2024-07-04 21:21:47 INFO The form has been created
2024-07-04 21:22:31 INFO The form has been created
2024-07-04 21:22:42 INFO The form has been created
2024-07-04 21:47:32 INFO The form has been created
2024-07-04 21:47:58 INFO The form has been created
2024-07-04 21:48:15 INFO The form has been created
2024-07-04 21:48:15 INFO The form has been submitted and validated
2024-07-04 21:48:15 INFO The user has logged in
2024-07-04 21:49:25 INFO The form has been created
2024-07-04 21:49:30 INFO The form has been created
2024-07-04 21:49:30 INFO The form has been submitted and validated
2024-07-04 21:49:30 INFO The user has logged in
2024-07-04 21:49:57 INFO The form has been created
2024-07-04 21:50:05 INFO The form has been created
2024-07-04 21:50:27 INFO The form has been created
2024-07-04 21:50:27 INFO The form has been submitted and validated
2024-07-04 21:50:27 INFO The user has logged in
2024-07-04 22:19:43 INFO The form has been created
2024-07-04 22:19:43 ERROR Exception on /auth/login [GET]
Traceback (most recent call last):
  File "/home/Flasheeta/.virtualenvs/myenv/lib/python3.8/site-packages/sqlalchemy/engine/base.py", line 1967, in _exec_single_context
    self.dialect.do_execute(
  File "/home/Flasheeta/.virtualenvs/myenv/lib/python3.8/site-packages/sqlalchemy/engine/default.py", line 924, in do_execute
    cursor.execute(statement, parameters)
  File "/home/Flasheeta/.virtualenvs/myenv/lib/python3.8/site-packages/MySQLdb/cursors.py", line 179, in execute
    res = self._query(mogrified_query)
  File "/home/Flasheeta/.virtualenvs/myenv/lib/python3.8/site-packages/MySQLdb/cursors.py", line 330, in _query
    db.query(q)
  File "/home/Flasheeta/.virtualenvs/myenv/lib/python3.8/site-packages/MySQLdb/connections.py", line 261, in query
    _mysql.connection.query(self, query)
MySQLdb.OperationalError: (4031, 'The client was disconnected by the server because of inactivity. See wait_timeout and interactive_timeout for configuring this behavior.')

The above exception was the direct cause of the following exception:

Traceback (most recent call last):
  File "/home/Flasheeta/.virtualenvs/myenv/lib/python3.8/site-packages/flask/app.py", line 1473, in wsgi_app
    response = self.full_dispatch_request()
  File "/home/Flasheeta/.virtualenvs/myenv/lib/python3.8/site-packages/flask/app.py", line 882, in full_dispatch_request
    rv = self.handle_user_exception(e)
  File "/home/Flasheeta/.virtualenvs/myenv/lib/python3.8/site-packages/flask/app.py", line 880, in full_dispatch_request
    rv = self.dispatch_request()
  File "/home/Flasheeta/.virtualenvs/myenv/lib/python3.8/site-packages/flask/app.py", line 865, in dispatch_request
    return self.ensure_sync(self.view_functions[rule.endpoint])(**view_args)  # type: ignore[no-any-return]
  File "/home/Flasheeta/Flasheeta/app/web_routes/auth_routes.py", line 62, in login
    return render_template('login.html', form=form)
  File "/home/Flasheeta/.virtualenvs/myenv/lib/python3.8/site-packages/flask/templating.py", line 150, in render_template
    return _render(app, template, context)
  File "/home/Flasheeta/.virtualenvs/myenv/lib/python3.8/site-packages/flask/templating.py", line 127, in _render
    app.update_template_context(context)
  File "/home/Flasheeta/.virtualenvs/myenv/lib/python3.8/site-packages/flask/app.py", line 493, in update_template_context
    context.update(self.ensure_sync(func)())
  File "/home/Flasheeta/.virtualenvs/myenv/lib/python3.8/site-packages/flask_login/utils.py", line 405, in _user_context_processor
    return dict(current_user=_get_user())
  File "/home/Flasheeta/.virtualenvs/myenv/lib/python3.8/site-packages/flask_login/utils.py", line 370, in _get_user
    current_app.login_manager._load_user()
  File "/home/Flasheeta/.virtualenvs/myenv/lib/python3.8/site-packages/flask_login/login_manager.py", line 364, in _load_user
    user = self._user_callback(user_id)
  File "/home/Flasheeta/Flasheeta/app/__init__.py", line 54, in load_user
    return app.storage.get(User, user_id)
  File "/home/Flasheeta/Flasheeta/app/models/engine/db_storage.py", line 77, in get
    for obj in self.all().values():
  File "/home/Flasheeta/Flasheeta/app/models/engine/db_storage.py", line 36, in all
    query = self.db.session.query(c).all()
  File "/home/Flasheeta/.virtualenvs/myenv/lib/python3.8/site-packages/sqlalchemy/orm/query.py", line 2673, in all
    return self._iter().all()  # type: ignore
  File "/home/Flasheeta/.virtualenvs/myenv/lib/python3.8/site-packages/sqlalchemy/orm/query.py", line 2827, in _iter
    result: Union[ScalarResult[_T], Result[_T]] = self.session.execute(
  File "/home/Flasheeta/.virtualenvs/myenv/lib/python3.8/site-packages/sqlalchemy/orm/session.py", line 2351, in execute
    return self._execute_internal(
  File "/home/Flasheeta/.virtualenvs/myenv/lib/python3.8/site-packages/sqlalchemy/orm/session.py", line 2236, in _execute_internal
    result: Result[Any] = compile_state_cls.orm_execute_statement(
  File "/home/Flasheeta/.virtualenvs/myenv/lib/python3.8/site-packages/sqlalchemy/orm/context.py", line 293, in orm_execute_statement
    result = conn.execute(
  File "/home/Flasheeta/.virtualenvs/myenv/lib/python3.8/site-packages/sqlalchemy/engine/base.py", line 1418, in execute
    return meth(
  File "/home/Flasheeta/.virtualenvs/myenv/lib/python3.8/site-packages/sqlalchemy/sql/elements.py", line 515, in _execute_on_connection
    return connection._execute_clauseelement(
  File "/home/Flasheeta/.virtualenvs/myenv/lib/python3.8/site-packages/sqlalchemy/engine/base.py", line 1640, in _execute_clauseelement
    ret = self._execute_context(
  File "/home/Flasheeta/.virtualenvs/myenv/lib/python3.8/site-packages/sqlalchemy/engine/base.py", line 1846, in _execute_context
    return self._exec_single_context(
  File "/home/Flasheeta/.virtualenvs/myenv/lib/python3.8/site-packages/sqlalchemy/engine/base.py", line 1986, in _exec_single_context
    self._handle_dbapi_exception(
  File "/home/Flasheeta/.virtualenvs/myenv/lib/python3.8/site-packages/sqlalchemy/engine/base.py", line 2353, in _handle_dbapi_exception
    raise sqlalchemy_exception.with_traceback(exc_info[2]) from e
  File "/home/Flasheeta/.virtualenvs/myenv/lib/python3.8/site-packages/sqlalchemy/engine/base.py", line 1967, in _exec_single_context
    self.dialect.do_execute(
  File "/home/Flasheeta/.virtualenvs/myenv/lib/python3.8/site-packages/sqlalchemy/engine/default.py", line 924, in do_execute
    cursor.execute(statement, parameters)
  File "/home/Flasheeta/.virtualenvs/myenv/lib/python3.8/site-packages/MySQLdb/cursors.py", line 179, in execute
    res = self._query(mogrified_query)
  File "/home/Flasheeta/.virtualenvs/myenv/lib/python3.8/site-packages/MySQLdb/cursors.py", line 330, in _query
    db.query(q)
  File "/home/Flasheeta/.virtualenvs/myenv/lib/python3.8/site-packages/MySQLdb/connections.py", line 261, in query
    _mysql.connection.query(self, query)
sqlalchemy.exc.OperationalError: (MySQLdb.OperationalError) (4031, 'The client was disconnected by the server because of inactivity. See wait_timeout and interactive_timeout for configuring this behavior.')
[SQL: SELECT users.name AS users_name, users.id AS users_id, users.created_at AS users_created_at, users.updated_at AS users_updated_at 
FROM users]
(Background on this error at: https://sqlalche.me/e/20/e3q8)
2024-07-04 22:20:48 INFO The form has been created
2024-07-04 22:21:18 INFO The form has been created
2024-07-04 23:55:47 INFO The form has been created
2024-07-05 02:17:46 INFO The form has been created
2024-07-05 02:34:16 INFO The form has been created
2024-07-05 03:13:15 INFO The form has been created
2024-07-05 14:06:53 INFO The form has been created
2024-07-05 14:06:53 ERROR OSError: write error
2024-07-05 14:21:24 ERROR Exception on /auth/register [GET]
Traceback (most recent call last):
  File "/home/Flasheeta/.virtualenvs/myenv/lib/python3.8/site-packages/sqlalchemy/engine/base.py", line 1967, in _exec_single_context
    self.dialect.do_execute(
  File "/home/Flasheeta/.virtualenvs/myenv/lib/python3.8/site-packages/sqlalchemy/engine/default.py", line 924, in do_execute
    cursor.execute(statement, parameters)
  File "/home/Flasheeta/.virtualenvs/myenv/lib/python3.8/site-packages/MySQLdb/cursors.py", line 179, in execute
    res = self._query(mogrified_query)
  File "/home/Flasheeta/.virtualenvs/myenv/lib/python3.8/site-packages/MySQLdb/cursors.py", line 330, in _query
    db.query(q)
  File "/home/Flasheeta/.virtualenvs/myenv/lib/python3.8/site-packages/MySQLdb/connections.py", line 261, in query
    _mysql.connection.query(self, query)
MySQLdb.OperationalError: (4031, 'The client was disconnected by the server because of inactivity. See wait_timeout and interactive_timeout for configuring this behavior.')

The above exception was the direct cause of the following exception:

Traceback (most recent call last):
  File "/home/Flasheeta/.virtualenvs/myenv/lib/python3.8/site-packages/flask/app.py", line 1473, in wsgi_app
    response = self.full_dispatch_request()
  File "/home/Flasheeta/.virtualenvs/myenv/lib/python3.8/site-packages/flask/app.py", line 882, in full_dispatch_request
    rv = self.handle_user_exception(e)
  File "/home/Flasheeta/.virtualenvs/myenv/lib/python3.8/site-packages/flask/app.py", line 880, in full_dispatch_request
    rv = self.dispatch_request()
  File "/home/Flasheeta/.virtualenvs/myenv/lib/python3.8/site-packages/flask/app.py", line 865, in dispatch_request
    return self.ensure_sync(self.view_functions[rule.endpoint])(**view_args)  # type: ignore[no-any-return]
  File "/home/Flasheeta/Flasheeta/app/web_routes/auth_routes.py", line 37, in register
    return render_template('register.html', form=form)
  File "/home/Flasheeta/.virtualenvs/myenv/lib/python3.8/site-packages/flask/templating.py", line 150, in render_template
    return _render(app, template, context)
  File "/home/Flasheeta/.virtualenvs/myenv/lib/python3.8/site-packages/flask/templating.py", line 127, in _render
    app.update_template_context(context)
  File "/home/Flasheeta/.virtualenvs/myenv/lib/python3.8/site-packages/flask/app.py", line 493, in update_template_context
    context.update(self.ensure_sync(func)())
  File "/home/Flasheeta/.virtualenvs/myenv/lib/python3.8/site-packages/flask_login/utils.py", line 405, in _user_context_processor
    return dict(current_user=_get_user())
  File "/home/Flasheeta/.virtualenvs/myenv/lib/python3.8/site-packages/flask_login/utils.py", line 370, in _get_user
    current_app.login_manager._load_user()
  File "/home/Flasheeta/.virtualenvs/myenv/lib/python3.8/site-packages/flask_login/login_manager.py", line 364, in _load_user
    user = self._user_callback(user_id)
  File "/home/Flasheeta/Flasheeta/app/__init__.py", line 54, in load_user
    return app.storage.get(User, user_id)
  File "/home/Flasheeta/Flasheeta/app/models/engine/db_storage.py", line 77, in get
    for obj in self.all().values():
  File "/home/Flasheeta/Flasheeta/app/models/engine/db_storage.py", line 36, in all
    query = self.db.session.query(c).all()
  File "/home/Flasheeta/.virtualenvs/myenv/lib/python3.8/site-packages/sqlalchemy/orm/query.py", line 2673, in all
    return self._iter().all()  # type: ignore
  File "/home/Flasheeta/.virtualenvs/myenv/lib/python3.8/site-packages/sqlalchemy/orm/query.py", line 2827, in _iter
    result: Union[ScalarResult[_T], Result[_T]] = self.session.execute(
  File "/home/Flasheeta/.virtualenvs/myenv/lib/python3.8/site-packages/sqlalchemy/orm/session.py", line 2351, in execute
    return self._execute_internal(
  File "/home/Flasheeta/.virtualenvs/myenv/lib/python3.8/site-packages/sqlalchemy/orm/session.py", line 2236, in _execute_internal
    result: Result[Any] = compile_state_cls.orm_execute_statement(
  File "/home/Flasheeta/.virtualenvs/myenv/lib/python3.8/site-packages/sqlalchemy/orm/context.py", line 293, in orm_execute_statement
    result = conn.execute(
  File "/home/Flasheeta/.virtualenvs/myenv/lib/python3.8/site-packages/sqlalchemy/engine/base.py", line 1418, in execute
    return meth(
  File "/home/Flasheeta/.virtualenvs/myenv/lib/python3.8/site-packages/sqlalchemy/sql/elements.py", line 515, in _execute_on_connection
    return connection._execute_clauseelement(
  File "/home/Flasheeta/.virtualenvs/myenv/lib/python3.8/site-packages/sqlalchemy/engine/base.py", line 1640, in _execute_clauseelement
    ret = self._execute_context(
  File "/home/Flasheeta/.virtualenvs/myenv/lib/python3.8/site-packages/sqlalchemy/engine/base.py", line 1846, in _execute_context
    return self._exec_single_context(
  File "/home/Flasheeta/.virtualenvs/myenv/lib/python3.8/site-packages/sqlalchemy/engine/base.py", line 1986, in _exec_single_context
    self._handle_dbapi_exception(
  File "/home/Flasheeta/.virtualenvs/myenv/lib/python3.8/site-packages/sqlalchemy/engine/base.py", line 2353, in _handle_dbapi_exception
    raise sqlalchemy_exception.with_traceback(exc_info[2]) from e
  File "/home/Flasheeta/.virtualenvs/myenv/lib/python3.8/site-packages/sqlalchemy/engine/base.py", line 1967, in _exec_single_context
    self.dialect.do_execute(
  File "/home/Flasheeta/.virtualenvs/myenv/lib/python3.8/site-packages/sqlalchemy/engine/default.py", line 924, in do_execute
    cursor.execute(statement, parameters)
  File "/home/Flasheeta/.virtualenvs/myenv/lib/python3.8/site-packages/MySQLdb/cursors.py", line 179, in execute
    res = self._query(mogrified_query)
  File "/home/Flasheeta/.virtualenvs/myenv/lib/python3.8/site-packages/MySQLdb/cursors.py", line 330, in _query
    db.query(q)
  File "/home/Flasheeta/.virtualenvs/myenv/lib/python3.8/site-packages/MySQLdb/connections.py", line 261, in query
    _mysql.connection.query(self, query)
sqlalchemy.exc.OperationalError: (MySQLdb.OperationalError) (4031, 'The client was disconnected by the server because of inactivity. See wait_timeout and interactive_timeout for configuring this behavior.')
[SQL: SELECT users.name AS users_name, users.id AS users_id, users.created_at AS users_created_at, users.updated_at AS users_updated_at 
FROM users]
(Background on this error at: https://sqlalche.me/e/20/e3q8)
2024-07-05 14:33:32 ERROR Exception on /users/me/flashcards/new [GET]
Traceback (most recent call last):
  File "/home/Flasheeta/.virtualenvs/myenv/lib/python3.8/site-packages/sqlalchemy/engine/base.py", line 1967, in _exec_single_context
    self.dialect.do_execute(
  File "/home/Flasheeta/.virtualenvs/myenv/lib/python3.8/site-packages/sqlalchemy/engine/default.py", line 924, in do_execute
    cursor.execute(statement, parameters)
  File "/home/Flasheeta/.virtualenvs/myenv/lib/python3.8/site-packages/MySQLdb/cursors.py", line 179, in execute
    res = self._query(mogrified_query)
  File "/home/Flasheeta/.virtualenvs/myenv/lib/python3.8/site-packages/MySQLdb/cursors.py", line 330, in _query
    db.query(q)
  File "/home/Flasheeta/.virtualenvs/myenv/lib/python3.8/site-packages/MySQLdb/connections.py", line 261, in query
    _mysql.connection.query(self, query)
MySQLdb.OperationalError: (4031, 'The client was disconnected by the server because of inactivity. See wait_timeout and interactive_timeout for configuring this behavior.')

The above exception was the direct cause of the following exception:

Traceback (most recent call last):
  File "/home/Flasheeta/.virtualenvs/myenv/lib/python3.8/site-packages/flask/app.py", line 1473, in wsgi_app
    response = self.full_dispatch_request()
  File "/home/Flasheeta/.virtualenvs/myenv/lib/python3.8/site-packages/flask/app.py", line 882, in full_dispatch_request
    rv = self.handle_user_exception(e)
  File "/home/Flasheeta/.virtualenvs/myenv/lib/python3.8/site-packages/flask/app.py", line 880, in full_dispatch_request
    rv = self.dispatch_request()
  File "/home/Flasheeta/.virtualenvs/myenv/lib/python3.8/site-packages/flask/app.py", line 865, in dispatch_request
    return self.ensure_sync(self.view_functions[rule.endpoint])(**view_args)  # type: ignore[no-any-return]
  File "/home/Flasheeta/.virtualenvs/myenv/lib/python3.8/site-packages/flask_login/utils.py", line 284, in decorated_view
    elif not current_user.is_authenticated:
  File "/home/Flasheeta/.virtualenvs/myenv/lib/python3.8/site-packages/werkzeug/local.py", line 318, in __get__
    obj = instance._get_current_object()
  File "/home/Flasheeta/.virtualenvs/myenv/lib/python3.8/site-packages/werkzeug/local.py", line 526, in _get_current_object
    return get_name(local())
  File "/home/Flasheeta/.virtualenvs/myenv/lib/python3.8/site-packages/flask_login/utils.py", line 25, in <lambda>
    current_user = LocalProxy(lambda: _get_user())
  File "/home/Flasheeta/.virtualenvs/myenv/lib/python3.8/site-packages/flask_login/utils.py", line 370, in _get_user
    current_app.login_manager._load_user()
  File "/home/Flasheeta/.virtualenvs/myenv/lib/python3.8/site-packages/flask_login/login_manager.py", line 364, in _load_user
    user = self._user_callback(user_id)
  File "/home/Flasheeta/Flasheeta/app/__init__.py", line 54, in load_user
    return app.storage.get(User, user_id)
  File "/home/Flasheeta/Flasheeta/app/models/engine/db_storage.py", line 77, in get
    for obj in self.all().values():
  File "/home/Flasheeta/Flasheeta/app/models/engine/db_storage.py", line 36, in all
    query = self.db.session.query(c).all()
  File "/home/Flasheeta/.virtualenvs/myenv/lib/python3.8/site-packages/sqlalchemy/orm/query.py", line 2673, in all
    return self._iter().all()  # type: ignore
  File "/home/Flasheeta/.virtualenvs/myenv/lib/python3.8/site-packages/sqlalchemy/orm/query.py", line 2827, in _iter
    result: Union[ScalarResult[_T], Result[_T]] = self.session.execute(
  File "/home/Flasheeta/.virtualenvs/myenv/lib/python3.8/site-packages/sqlalchemy/orm/session.py", line 2351, in execute
    return self._execute_internal(
  File "/home/Flasheeta/.virtualenvs/myenv/lib/python3.8/site-packages/sqlalchemy/orm/session.py", line 2236, in _execute_internal
    result: Result[Any] = compile_state_cls.orm_execute_statement(
  File "/home/Flasheeta/.virtualenvs/myenv/lib/python3.8/site-packages/sqlalchemy/orm/context.py", line 293, in orm_execute_statement
    result = conn.execute(
  File "/home/Flasheeta/.virtualenvs/myenv/lib/python3.8/site-packages/sqlalchemy/engine/base.py", line 1418, in execute
    return meth(
  File "/home/Flasheeta/.virtualenvs/myenv/lib/python3.8/site-packages/sqlalchemy/sql/elements.py", line 515, in _execute_on_connection
    return connection._execute_clauseelement(
  File "/home/Flasheeta/.virtualenvs/myenv/lib/python3.8/site-packages/sqlalchemy/engine/base.py", line 1640, in _execute_clauseelement
    ret = self._execute_context(
  File "/home/Flasheeta/.virtualenvs/myenv/lib/python3.8/site-packages/sqlalchemy/engine/base.py", line 1846, in _execute_context
    return self._exec_single_context(
  File "/home/Flasheeta/.virtualenvs/myenv/lib/python3.8/site-packages/sqlalchemy/engine/base.py", line 1986, in _exec_single_context
    self._handle_dbapi_exception(
  File "/home/Flasheeta/.virtualenvs/myenv/lib/python3.8/site-packages/sqlalchemy/engine/base.py", line 2353, in _handle_dbapi_exception
    raise sqlalchemy_exception.with_traceback(exc_info[2]) from e
  File "/home/Flasheeta/.virtualenvs/myenv/lib/python3.8/site-packages/sqlalchemy/engine/base.py", line 1967, in _exec_single_context
    self.dialect.do_execute(
  File "/home/Flasheeta/.virtualenvs/myenv/lib/python3.8/site-packages/sqlalchemy/engine/default.py", line 924, in do_execute
    cursor.execute(statement, parameters)
  File "/home/Flasheeta/.virtualenvs/myenv/lib/python3.8/site-packages/MySQLdb/cursors.py", line 179, in execute
    res = self._query(mogrified_query)
  File "/home/Flasheeta/.virtualenvs/myenv/lib/python3.8/site-packages/MySQLdb/cursors.py", line 330, in _query
    db.query(q)
  File "/home/Flasheeta/.virtualenvs/myenv/lib/python3.8/site-packages/MySQLdb/connections.py", line 261, in query
    _mysql.connection.query(self, query)
sqlalchemy.exc.OperationalError: (MySQLdb.OperationalError) (4031, 'The client was disconnected by the server because of inactivity. See wait_timeout and interactive_timeout for configuring this behavior.')
[SQL: SELECT users.name AS users_name, users.id AS users_id, users.created_at AS users_created_at, users.updated_at AS users_updated_at 
FROM users]
(Background on this error at: https://sqlalche.me/e/20/e3q8)
2024-07-07 15:49:51 ERROR Error running WSGI application
2024-07-07 15:49:51 ERROR RuntimeError: Either 'SQLALCHEMY_DATABASE_URI' or 'SQLALCHEMY_BINDS' must be set.
2024-07-07 15:49:51 ERROR   File "/var/www/flasheeta_pythonanywhere_com_wsgi.py", line 20, in <module>
2024-07-07 15:49:51 ERROR     from run import app as application  # noqa
2024-07-07 15:49:51 ERROR 
2024-07-07 15:49:51 ERROR   File "/home/Flasheeta/Flasheeta/run.py", line 4, in <module>
2024-07-07 15:49:51 ERROR     app = create_app()
2024-07-07 15:49:51 ERROR 
2024-07-07 15:49:51 ERROR   File "/home/Flasheeta/Flasheeta/app/__init__.py", line 23, in create_app
2024-07-07 15:49:51 ERROR     db.init_app(app)
2024-07-07 15:49:51 ERROR 
2024-07-07 15:49:51 ERROR   File "/home/Flasheeta/.virtualenvs/myenv/lib/python3.8/site-packages/flask_sqlalchemy/extension.py", line 355, in init_app
2024-07-07 15:49:51 ERROR     raise RuntimeError(
2024-07-07 15:49:51 ERROR ***************************************************
2024-07-07 15:49:51 ERROR If you're seeing an import error and don't know why,
2024-07-07 15:49:51 ERROR we have a dedicated help page to help you debug: 
2024-07-07 15:49:51 ERROR https://help.pythonanywhere.com/pages/DebuggingImportError/
2024-07-07 15:49:51 ERROR ***************************************************
2024-07-07 15:49:54 ERROR Error running WSGI application
2024-07-07 15:49:54 ERROR RuntimeError: Either 'SQLALCHEMY_DATABASE_URI' or 'SQLALCHEMY_BINDS' must be set.
2024-07-07 15:49:54 ERROR   File "/var/www/flasheeta_pythonanywhere_com_wsgi.py", line 20, in <module>
2024-07-07 15:49:54 ERROR     from run import app as application  # noqa
2024-07-07 15:49:54 ERROR 
2024-07-07 15:49:54 ERROR   File "/home/Flasheeta/Flasheeta/run.py", line 4, in <module>
2024-07-07 15:49:54 ERROR     app = create_app()
2024-07-07 15:49:54 ERROR 
2024-07-07 15:49:54 ERROR   File "/home/Flasheeta/Flasheeta/app/__init__.py", line 23, in create_app
2024-07-07 15:49:54 ERROR     db.init_app(app)
2024-07-07 15:49:54 ERROR 
2024-07-07 15:49:54 ERROR   File "/home/Flasheeta/.virtualenvs/myenv/lib/python3.8/site-packages/flask_sqlalchemy/extension.py", line 355, in init_app
2024-07-07 15:49:54 ERROR     raise RuntimeError(
2024-07-07 15:49:54 ERROR ***************************************************
2024-07-07 15:49:54 ERROR If you're seeing an import error and don't know why,
2024-07-07 15:49:54 ERROR we have a dedicated help page to help you debug: 
2024-07-07 15:49:54 ERROR https://help.pythonanywhere.com/pages/DebuggingImportError/
2024-07-07 15:49:54 ERROR ***************************************************
2024-07-07 15:49:55 ERROR Error running WSGI application
2024-07-07 15:49:55 ERROR RuntimeError: Either 'SQLALCHEMY_DATABASE_URI' or 'SQLALCHEMY_BINDS' must be set.
2024-07-07 15:49:55 ERROR   File "/var/www/flasheeta_pythonanywhere_com_wsgi.py", line 20, in <module>
2024-07-07 15:49:55 ERROR     from run import app as application  # noqa
2024-07-07 15:49:55 ERROR 
2024-07-07 15:49:55 ERROR   File "/home/Flasheeta/Flasheeta/run.py", line 4, in <module>
2024-07-07 15:49:55 ERROR     app = create_app()
2024-07-07 15:49:55 ERROR 
2024-07-07 15:49:55 ERROR   File "/home/Flasheeta/Flasheeta/app/__init__.py", line 23, in create_app
2024-07-07 15:49:55 ERROR     db.init_app(app)
2024-07-07 15:49:55 ERROR 
2024-07-07 15:49:55 ERROR   File "/home/Flasheeta/.virtualenvs/myenv/lib/python3.8/site-packages/flask_sqlalchemy/extension.py", line 355, in init_app
2024-07-07 15:49:55 ERROR     raise RuntimeError(
2024-07-07 15:49:55 ERROR ***************************************************
2024-07-07 15:49:55 ERROR If you're seeing an import error and don't know why,
2024-07-07 15:49:55 ERROR we have a dedicated help page to help you debug: 
2024-07-07 15:49:55 ERROR https://help.pythonanywhere.com/pages/DebuggingImportError/
2024-07-07 15:49:55 ERROR ***************************************************
2024-07-07 15:50:47 ERROR Error running WSGI application
2024-07-07 15:50:47 ERROR RuntimeError: Either 'SQLALCHEMY_DATABASE_URI' or 'SQLALCHEMY_BINDS' must be set.
2024-07-07 15:50:47 ERROR   File "/var/www/flasheeta_pythonanywhere_com_wsgi.py", line 20, in <module>
2024-07-07 15:50:47 ERROR     from run import app as application  # noqa
2024-07-07 15:50:47 ERROR 
2024-07-07 15:50:47 ERROR   File "/home/Flasheeta/Flasheeta/run.py", line 4, in <module>
2024-07-07 15:50:47 ERROR     app = create_app()
2024-07-07 15:50:47 ERROR 
2024-07-07 15:50:47 ERROR   File "/home/Flasheeta/Flasheeta/app/__init__.py", line 23, in create_app
2024-07-07 15:50:47 ERROR     db.init_app(app)
2024-07-07 15:50:47 ERROR 
2024-07-07 15:50:47 ERROR   File "/home/Flasheeta/.virtualenvs/myenv/lib/python3.8/site-packages/flask_sqlalchemy/extension.py", line 355, in init_app
2024-07-07 15:50:47 ERROR     raise RuntimeError(
2024-07-07 15:50:47 ERROR ***************************************************
2024-07-07 15:50:47 ERROR If you're seeing an import error and don't know why,
2024-07-07 15:50:47 ERROR we have a dedicated help page to help you debug: 
2024-07-07 15:50:47 ERROR https://help.pythonanywhere.com/pages/DebuggingImportError/
2024-07-07 15:50:47 ERROR ***************************************************
2024-07-07 15:52:45 ERROR Error running WSGI application
2024-07-07 15:52:45 ERROR RuntimeError: Either 'SQLALCHEMY_DATABASE_URI' or 'SQLALCHEMY_BINDS' must be set.
2024-07-07 15:52:45 ERROR   File "/var/www/flasheeta_pythonanywhere_com_wsgi.py", line 20, in <module>
2024-07-07 15:52:45 ERROR     from run import app as application  # noqa
2024-07-07 15:52:45 ERROR 
2024-07-07 15:52:45 ERROR   File "/home/Flasheeta/Flasheeta/run.py", line 4, in <module>
2024-07-07 15:52:45 ERROR     app = create_app()
2024-07-07 15:52:45 ERROR 
2024-07-07 15:52:45 ERROR   File "/home/Flasheeta/Flasheeta/app/__init__.py", line 23, in create_app
2024-07-07 15:52:45 ERROR     db.init_app(app)
2024-07-07 15:52:45 ERROR 
2024-07-07 15:52:45 ERROR   File "/home/Flasheeta/.virtualenvs/myenv/lib/python3.8/site-packages/flask_sqlalchemy/extension.py", line 355, in init_app
2024-07-07 15:52:45 ERROR     raise RuntimeError(
2024-07-07 15:52:45 ERROR ***************************************************
2024-07-07 15:52:45 ERROR If you're seeing an import error and don't know why,
2024-07-07 15:52:45 ERROR we have a dedicated help page to help you debug: 
2024-07-07 15:52:45 ERROR https://help.pythonanywhere.com/pages/DebuggingImportError/
2024-07-07 15:52:45 ERROR ***************************************************
2024-07-07 15:52:47 ERROR Error running WSGI application
2024-07-07 15:52:47 ERROR RuntimeError: Either 'SQLALCHEMY_DATABASE_URI' or 'SQLALCHEMY_BINDS' must be set.
2024-07-07 15:52:47 ERROR   File "/var/www/flasheeta_pythonanywhere_com_wsgi.py", line 20, in <module>
2024-07-07 15:52:47 ERROR     from run import app as application  # noqa
2024-07-07 15:52:47 ERROR 
2024-07-07 15:52:47 ERROR   File "/home/Flasheeta/Flasheeta/run.py", line 4, in <module>
2024-07-07 15:52:47 ERROR     app = create_app()
2024-07-07 15:52:47 ERROR 
2024-07-07 15:52:47 ERROR   File "/home/Flasheeta/Flasheeta/app/__init__.py", line 23, in create_app
2024-07-07 15:52:47 ERROR     db.init_app(app)
2024-07-07 15:52:47 ERROR 
2024-07-07 15:52:47 ERROR   File "/home/Flasheeta/.virtualenvs/myenv/lib/python3.8/site-packages/flask_sqlalchemy/extension.py", line 355, in init_app
2024-07-07 15:52:47 ERROR     raise RuntimeError(
2024-07-07 15:52:47 ERROR ***************************************************
2024-07-07 15:52:47 ERROR If you're seeing an import error and don't know why,
2024-07-07 15:52:47 ERROR we have a dedicated help page to help you debug: 
2024-07-07 15:52:47 ERROR https://help.pythonanywhere.com/pages/DebuggingImportError/
2024-07-07 15:52:47 ERROR ***************************************************
2024-07-07 15:52:48 ERROR Error running WSGI application
2024-07-07 15:52:48 ERROR RuntimeError: Either 'SQLALCHEMY_DATABASE_URI' or 'SQLALCHEMY_BINDS' must be set.
2024-07-07 15:52:48 ERROR   File "/var/www/flasheeta_pythonanywhere_com_wsgi.py", line 20, in <module>
2024-07-07 15:52:48 ERROR     from run import app as application  # noqa
2024-07-07 15:52:48 ERROR 
2024-07-07 15:52:48 ERROR   File "/home/Flasheeta/Flasheeta/run.py", line 4, in <module>
2024-07-07 15:52:48 ERROR     app = create_app()
2024-07-07 15:52:48 ERROR 
2024-07-07 15:52:48 ERROR   File "/home/Flasheeta/Flasheeta/app/__init__.py", line 23, in create_app
2024-07-07 15:52:48 ERROR     db.init_app(app)
2024-07-07 15:52:48 ERROR 
2024-07-07 15:52:48 ERROR   File "/home/Flasheeta/.virtualenvs/myenv/lib/python3.8/site-packages/flask_sqlalchemy/extension.py", line 355, in init_app
2024-07-07 15:52:48 ERROR     raise RuntimeError(
2024-07-07 15:52:48 ERROR ***************************************************
2024-07-07 15:52:48 ERROR If you're seeing an import error and don't know why,
2024-07-07 15:52:48 ERROR we have a dedicated help page to help you debug: 
2024-07-07 15:52:48 ERROR https://help.pythonanywhere.com/pages/DebuggingImportError/
2024-07-07 15:52:48 ERROR ***************************************************
2024-07-07 15:56:27 ERROR Error running WSGI application
2024-07-07 15:56:27 ERROR RuntimeError: Either 'SQLALCHEMY_DATABASE_URI' or 'SQLALCHEMY_BINDS' must be set.
2024-07-07 15:56:27 ERROR   File "/var/www/flasheeta_pythonanywhere_com_wsgi.py", line 20, in <module>
2024-07-07 15:56:27 ERROR     from run import app as application  # noqa
2024-07-07 15:56:27 ERROR 
2024-07-07 15:56:27 ERROR   File "/home/Flasheeta/Flasheeta/run.py", line 4, in <module>
2024-07-07 15:56:27 ERROR     app = create_app()
2024-07-07 15:56:27 ERROR 
2024-07-07 15:56:27 ERROR   File "/home/Flasheeta/Flasheeta/app/__init__.py", line 23, in create_app
2024-07-07 15:56:27 ERROR     db.init_app(app)
2024-07-07 15:56:27 ERROR 
2024-07-07 15:56:27 ERROR   File "/home/Flasheeta/.virtualenvs/myenv/lib/python3.8/site-packages/flask_sqlalchemy/extension.py", line 355, in init_app
2024-07-07 15:56:27 ERROR     raise RuntimeError(
2024-07-07 15:56:27 ERROR ***************************************************
2024-07-07 15:56:27 ERROR If you're seeing an import error and don't know why,
2024-07-07 15:56:27 ERROR we have a dedicated help page to help you debug: 
2024-07-07 15:56:27 ERROR https://help.pythonanywhere.com/pages/DebuggingImportError/
2024-07-07 15:56:27 ERROR ***************************************************
2024-07-07 15:56:28 ERROR Error running WSGI application
2024-07-07 15:56:28 ERROR RuntimeError: Either 'SQLALCHEMY_DATABASE_URI' or 'SQLALCHEMY_BINDS' must be set.
2024-07-07 15:56:28 ERROR   File "/var/www/flasheeta_pythonanywhere_com_wsgi.py", line 20, in <module>
2024-07-07 15:56:28 ERROR     from run import app as application  # noqa
2024-07-07 15:56:28 ERROR 
2024-07-07 15:56:28 ERROR   File "/home/Flasheeta/Flasheeta/run.py", line 4, in <module>
2024-07-07 15:56:28 ERROR     app = create_app()
2024-07-07 15:56:28 ERROR 
2024-07-07 15:56:28 ERROR   File "/home/Flasheeta/Flasheeta/app/__init__.py", line 23, in create_app
2024-07-07 15:56:28 ERROR     db.init_app(app)
2024-07-07 15:56:28 ERROR 
2024-07-07 15:56:28 ERROR   File "/home/Flasheeta/.virtualenvs/myenv/lib/python3.8/site-packages/flask_sqlalchemy/extension.py", line 355, in init_app
2024-07-07 15:56:28 ERROR     raise RuntimeError(
2024-07-07 15:56:28 ERROR ***************************************************
2024-07-07 15:56:28 ERROR If you're seeing an import error and don't know why,
2024-07-07 15:56:28 ERROR we have a dedicated help page to help you debug: 
2024-07-07 15:56:28 ERROR https://help.pythonanywhere.com/pages/DebuggingImportError/
2024-07-07 15:56:28 ERROR ***************************************************
2024-07-07 15:56:29 ERROR Error running WSGI application
2024-07-07 15:56:29 ERROR RuntimeError: Either 'SQLALCHEMY_DATABASE_URI' or 'SQLALCHEMY_BINDS' must be set.
2024-07-07 15:56:29 ERROR   File "/var/www/flasheeta_pythonanywhere_com_wsgi.py", line 20, in <module>
2024-07-07 15:56:29 ERROR     from run import app as application  # noqa
2024-07-07 15:56:29 ERROR 
2024-07-07 15:56:29 ERROR   File "/home/Flasheeta/Flasheeta/run.py", line 4, in <module>
2024-07-07 15:56:29 ERROR     app = create_app()
2024-07-07 15:56:29 ERROR 
2024-07-07 15:56:29 ERROR   File "/home/Flasheeta/Flasheeta/app/__init__.py", line 23, in create_app
2024-07-07 15:56:29 ERROR     db.init_app(app)
2024-07-07 15:56:29 ERROR 
2024-07-07 15:56:29 ERROR   File "/home/Flasheeta/.virtualenvs/myenv/lib/python3.8/site-packages/flask_sqlalchemy/extension.py", line 355, in init_app
2024-07-07 15:56:29 ERROR     raise RuntimeError(
2024-07-07 15:56:29 ERROR ***************************************************
2024-07-07 15:56:29 ERROR If you're seeing an import error and don't know why,
2024-07-07 15:56:29 ERROR we have a dedicated help page to help you debug: 
2024-07-07 15:56:29 ERROR https://help.pythonanywhere.com/pages/DebuggingImportError/
2024-07-07 15:56:29 ERROR ***************************************************
2024-07-07 15:58:52 ERROR Error running WSGI application
2024-07-07 15:58:52 ERROR RuntimeError: Either 'SQLALCHEMY_DATABASE_URI' or 'SQLALCHEMY_BINDS' must be set.
2024-07-07 15:58:52 ERROR   File "/var/www/flasheeta_pythonanywhere_com_wsgi.py", line 20, in <module>
2024-07-07 15:58:52 ERROR     from run import app as application  # noqa
2024-07-07 15:58:52 ERROR 
2024-07-07 15:58:52 ERROR   File "/home/Flasheeta/Flasheeta/run.py", line 4, in <module>
2024-07-07 15:58:52 ERROR     app = create_app()
2024-07-07 15:58:52 ERROR 
2024-07-07 15:58:52 ERROR   File "/home/Flasheeta/Flasheeta/app/__init__.py", line 23, in create_app
2024-07-07 15:58:52 ERROR     db.init_app(app)
2024-07-07 15:58:52 ERROR 
2024-07-07 15:58:52 ERROR   File "/home/Flasheeta/.virtualenvs/myenv/lib/python3.8/site-packages/flask_sqlalchemy/extension.py", line 355, in init_app
2024-07-07 15:58:52 ERROR     raise RuntimeError(
2024-07-07 15:58:52 ERROR ***************************************************
2024-07-07 15:58:52 ERROR If you're seeing an import error and don't know why,
2024-07-07 15:58:52 ERROR we have a dedicated help page to help you debug: 
2024-07-07 15:58:52 ERROR https://help.pythonanywhere.com/pages/DebuggingImportError/
2024-07-07 15:58:52 ERROR ***************************************************
2024-07-07 16:01:21 INFO The form has been created
2024-07-07 16:01:24 INFO The form has been created
2024-07-07 16:01:27 INFO The form has been created
2024-07-07 16:01:27 INFO The form has been submitted and validated
2024-07-07 16:01:27 INFO The user has logged in
2024-07-07 16:02:12 INFO The form has been created
2024-07-07 17:46:45 ERROR Exception on /users/me/decks [GET]
Traceback (most recent call last):
  File "/home/Flasheeta/.virtualenvs/myenv/lib/python3.8/site-packages/flask/app.py", line 1473, in wsgi_app
    response = self.full_dispatch_request()
  File "/home/Flasheeta/.virtualenvs/myenv/lib/python3.8/site-packages/flask/app.py", line 882, in full_dispatch_request
    rv = self.handle_user_exception(e)
  File "/home/Flasheeta/.virtualenvs/myenv/lib/python3.8/site-packages/flask/app.py", line 880, in full_dispatch_request
    rv = self.dispatch_request()
  File "/home/Flasheeta/.virtualenvs/myenv/lib/python3.8/site-packages/flask/app.py", line 865, in dispatch_request
    return self.ensure_sync(self.view_functions[rule.endpoint])(**view_args)  # type: ignore[no-any-return]
  File "/home/Flasheeta/.virtualenvs/myenv/lib/python3.8/site-packages/flask_login/utils.py", line 284, in decorated_view
    elif not current_user.is_authenticated:
  File "/home/Flasheeta/.virtualenvs/myenv/lib/python3.8/site-packages/werkzeug/local.py", line 318, in __get__
    obj = instance._get_current_object()
  File "/home/Flasheeta/.virtualenvs/myenv/lib/python3.8/site-packages/werkzeug/local.py", line 526, in _get_current_object
    return get_name(local())
  File "/home/Flasheeta/.virtualenvs/myenv/lib/python3.8/site-packages/flask_login/utils.py", line 25, in <lambda>
    current_user = LocalProxy(lambda: _get_user())
  File "/home/Flasheeta/.virtualenvs/myenv/lib/python3.8/site-packages/flask_login/utils.py", line 370, in _get_user
    current_app.login_manager._load_user()
  File "/home/Flasheeta/.virtualenvs/myenv/lib/python3.8/site-packages/flask_login/login_manager.py", line 364, in _load_user
    user = self._user_callback(user_id)
  File "/home/Flasheeta/Flasheeta/app/__init__.py", line 54, in load_user
    return app.storage.get(User, user_id)
  File "/home/Flasheeta/Flasheeta/app/models/engine/db_storage.py", line 109, in get
    for obj in self.all().values():
AttributeError: 'DBStorage' object has no attribute 'all'
2024-07-07 17:46:47 ERROR Exception on /users/me/decks [GET]
Traceback (most recent call last):
  File "/home/Flasheeta/.virtualenvs/myenv/lib/python3.8/site-packages/flask/app.py", line 1473, in wsgi_app
    response = self.full_dispatch_request()
  File "/home/Flasheeta/.virtualenvs/myenv/lib/python3.8/site-packages/flask/app.py", line 882, in full_dispatch_request
    rv = self.handle_user_exception(e)
  File "/home/Flasheeta/.virtualenvs/myenv/lib/python3.8/site-packages/flask/app.py", line 880, in full_dispatch_request
    rv = self.dispatch_request()
  File "/home/Flasheeta/.virtualenvs/myenv/lib/python3.8/site-packages/flask/app.py", line 865, in dispatch_request
    return self.ensure_sync(self.view_functions[rule.endpoint])(**view_args)  # type: ignore[no-any-return]
  File "/home/Flasheeta/.virtualenvs/myenv/lib/python3.8/site-packages/flask_login/utils.py", line 284, in decorated_view
    elif not current_user.is_authenticated:
  File "/home/Flasheeta/.virtualenvs/myenv/lib/python3.8/site-packages/werkzeug/local.py", line 318, in __get__
    obj = instance._get_current_object()
  File "/home/Flasheeta/.virtualenvs/myenv/lib/python3.8/site-packages/werkzeug/local.py", line 526, in _get_current_object
    return get_name(local())
  File "/home/Flasheeta/.virtualenvs/myenv/lib/python3.8/site-packages/flask_login/utils.py", line 25, in <lambda>
    current_user = LocalProxy(lambda: _get_user())
  File "/home/Flasheeta/.virtualenvs/myenv/lib/python3.8/site-packages/flask_login/utils.py", line 370, in _get_user
    current_app.login_manager._load_user()
  File "/home/Flasheeta/.virtualenvs/myenv/lib/python3.8/site-packages/flask_login/login_manager.py", line 364, in _load_user
    user = self._user_callback(user_id)
  File "/home/Flasheeta/Flasheeta/app/__init__.py", line 54, in load_user
    return app.storage.get(User, user_id)
  File "/home/Flasheeta/Flasheeta/app/models/engine/db_storage.py", line 109, in get
    for obj in self.all().values():
AttributeError: 'DBStorage' object has no attribute 'all'
2024-07-07 17:46:48 ERROR Exception on /users/me/decks [GET]
Traceback (most recent call last):
  File "/home/Flasheeta/.virtualenvs/myenv/lib/python3.8/site-packages/flask/app.py", line 1473, in wsgi_app
    response = self.full_dispatch_request()
  File "/home/Flasheeta/.virtualenvs/myenv/lib/python3.8/site-packages/flask/app.py", line 882, in full_dispatch_request
    rv = self.handle_user_exception(e)
  File "/home/Flasheeta/.virtualenvs/myenv/lib/python3.8/site-packages/flask/app.py", line 880, in full_dispatch_request
    rv = self.dispatch_request()
  File "/home/Flasheeta/.virtualenvs/myenv/lib/python3.8/site-packages/flask/app.py", line 865, in dispatch_request
    return self.ensure_sync(self.view_functions[rule.endpoint])(**view_args)  # type: ignore[no-any-return]
  File "/home/Flasheeta/.virtualenvs/myenv/lib/python3.8/site-packages/flask_login/utils.py", line 284, in decorated_view
    elif not current_user.is_authenticated:
  File "/home/Flasheeta/.virtualenvs/myenv/lib/python3.8/site-packages/werkzeug/local.py", line 318, in __get__
    obj = instance._get_current_object()
  File "/home/Flasheeta/.virtualenvs/myenv/lib/python3.8/site-packages/werkzeug/local.py", line 526, in _get_current_object
    return get_name(local())
  File "/home/Flasheeta/.virtualenvs/myenv/lib/python3.8/site-packages/flask_login/utils.py", line 25, in <lambda>
    current_user = LocalProxy(lambda: _get_user())
  File "/home/Flasheeta/.virtualenvs/myenv/lib/python3.8/site-packages/flask_login/utils.py", line 370, in _get_user
    current_app.login_manager._load_user()
  File "/home/Flasheeta/.virtualenvs/myenv/lib/python3.8/site-packages/flask_login/login_manager.py", line 364, in _load_user
    user = self._user_callback(user_id)
  File "/home/Flasheeta/Flasheeta/app/__init__.py", line 54, in load_user
    return app.storage.get(User, user_id)
  File "/home/Flasheeta/Flasheeta/app/models/engine/db_storage.py", line 109, in get
    for obj in self.all().values():
AttributeError: 'DBStorage' object has no attribute 'all'
2024-07-07 17:46:49 ERROR Exception on /users/me/decks [GET]
Traceback (most recent call last):
  File "/home/Flasheeta/.virtualenvs/myenv/lib/python3.8/site-packages/flask/app.py", line 1473, in wsgi_app
    response = self.full_dispatch_request()
  File "/home/Flasheeta/.virtualenvs/myenv/lib/python3.8/site-packages/flask/app.py", line 882, in full_dispatch_request
    rv = self.handle_user_exception(e)
  File "/home/Flasheeta/.virtualenvs/myenv/lib/python3.8/site-packages/flask/app.py", line 880, in full_dispatch_request
    rv = self.dispatch_request()
  File "/home/Flasheeta/.virtualenvs/myenv/lib/python3.8/site-packages/flask/app.py", line 865, in dispatch_request
    return self.ensure_sync(self.view_functions[rule.endpoint])(**view_args)  # type: ignore[no-any-return]
  File "/home/Flasheeta/.virtualenvs/myenv/lib/python3.8/site-packages/flask_login/utils.py", line 284, in decorated_view
    elif not current_user.is_authenticated:
  File "/home/Flasheeta/.virtualenvs/myenv/lib/python3.8/site-packages/werkzeug/local.py", line 318, in __get__
    obj = instance._get_current_object()
  File "/home/Flasheeta/.virtualenvs/myenv/lib/python3.8/site-packages/werkzeug/local.py", line 526, in _get_current_object
    return get_name(local())
  File "/home/Flasheeta/.virtualenvs/myenv/lib/python3.8/site-packages/flask_login/utils.py", line 25, in <lambda>
    current_user = LocalProxy(lambda: _get_user())
  File "/home/Flasheeta/.virtualenvs/myenv/lib/python3.8/site-packages/flask_login/utils.py", line 370, in _get_user
    current_app.login_manager._load_user()
  File "/home/Flasheeta/.virtualenvs/myenv/lib/python3.8/site-packages/flask_login/login_manager.py", line 364, in _load_user
    user = self._user_callback(user_id)
  File "/home/Flasheeta/Flasheeta/app/__init__.py", line 54, in load_user
    return app.storage.get(User, user_id)
  File "/home/Flasheeta/Flasheeta/app/models/engine/db_storage.py", line 109, in get
    for obj in self.all().values():
AttributeError: 'DBStorage' object has no attribute 'all'
2024-07-07 17:47:17 ERROR Exception on /users/me/decks [GET]
Traceback (most recent call last):
  File "/home/Flasheeta/.virtualenvs/myenv/lib/python3.8/site-packages/flask/app.py", line 1473, in wsgi_app
    response = self.full_dispatch_request()
  File "/home/Flasheeta/.virtualenvs/myenv/lib/python3.8/site-packages/flask/app.py", line 882, in full_dispatch_request
    rv = self.handle_user_exception(e)
  File "/home/Flasheeta/.virtualenvs/myenv/lib/python3.8/site-packages/flask/app.py", line 880, in full_dispatch_request
    rv = self.dispatch_request()
  File "/home/Flasheeta/.virtualenvs/myenv/lib/python3.8/site-packages/flask/app.py", line 865, in dispatch_request
    return self.ensure_sync(self.view_functions[rule.endpoint])(**view_args)  # type: ignore[no-any-return]
  File "/home/Flasheeta/.virtualenvs/myenv/lib/python3.8/site-packages/flask_login/utils.py", line 284, in decorated_view
    elif not current_user.is_authenticated:
  File "/home/Flasheeta/.virtualenvs/myenv/lib/python3.8/site-packages/werkzeug/local.py", line 318, in __get__
    obj = instance._get_current_object()
  File "/home/Flasheeta/.virtualenvs/myenv/lib/python3.8/site-packages/werkzeug/local.py", line 526, in _get_current_object
    return get_name(local())
  File "/home/Flasheeta/.virtualenvs/myenv/lib/python3.8/site-packages/flask_login/utils.py", line 25, in <lambda>
    current_user = LocalProxy(lambda: _get_user())
  File "/home/Flasheeta/.virtualenvs/myenv/lib/python3.8/site-packages/flask_login/utils.py", line 370, in _get_user
    current_app.login_manager._load_user()
  File "/home/Flasheeta/.virtualenvs/myenv/lib/python3.8/site-packages/flask_login/login_manager.py", line 364, in _load_user
    user = self._user_callback(user_id)
  File "/home/Flasheeta/Flasheeta/app/__init__.py", line 54, in load_user
    return app.storage.get(User, user_id)
  File "/home/Flasheeta/Flasheeta/app/models/engine/db_storage.py", line 109, in get
    for obj in self.all().values():
AttributeError: 'DBStorage' object has no attribute 'all'
2024-07-07 17:47:18 ERROR Exception on /auth/login [GET]
Traceback (most recent call last):
  File "/home/Flasheeta/.virtualenvs/myenv/lib/python3.8/site-packages/flask/app.py", line 1473, in wsgi_app
    response = self.full_dispatch_request()
  File "/home/Flasheeta/.virtualenvs/myenv/lib/python3.8/site-packages/flask/app.py", line 882, in full_dispatch_request
    rv = self.handle_user_exception(e)
  File "/home/Flasheeta/.virtualenvs/myenv/lib/python3.8/site-packages/flask/app.py", line 880, in full_dispatch_request
    rv = self.dispatch_request()
  File "/home/Flasheeta/.virtualenvs/myenv/lib/python3.8/site-packages/flask/app.py", line 865, in dispatch_request
    return self.ensure_sync(self.view_functions[rule.endpoint])(**view_args)  # type: ignore[no-any-return]
  File "/home/Flasheeta/Flasheeta/app/web_routes/auth_routes.py", line 62, in login
    return render_template('login.html', form=form)
  File "/home/Flasheeta/.virtualenvs/myenv/lib/python3.8/site-packages/flask/templating.py", line 150, in render_template
    return _render(app, template, context)
  File "/home/Flasheeta/.virtualenvs/myenv/lib/python3.8/site-packages/flask/templating.py", line 127, in _render
    app.update_template_context(context)
  File "/home/Flasheeta/.virtualenvs/myenv/lib/python3.8/site-packages/flask/app.py", line 493, in update_template_context
    context.update(self.ensure_sync(func)())
  File "/home/Flasheeta/.virtualenvs/myenv/lib/python3.8/site-packages/flask_login/utils.py", line 405, in _user_context_processor
    return dict(current_user=_get_user())
  File "/home/Flasheeta/.virtualenvs/myenv/lib/python3.8/site-packages/flask_login/utils.py", line 370, in _get_user
    current_app.login_manager._load_user()
  File "/home/Flasheeta/.virtualenvs/myenv/lib/python3.8/site-packages/flask_login/login_manager.py", line 364, in _load_user
    user = self._user_callback(user_id)
  File "/home/Flasheeta/Flasheeta/app/__init__.py", line 54, in load_user
    return app.storage.get(User, user_id)
  File "/home/Flasheeta/Flasheeta/app/models/engine/db_storage.py", line 109, in get
    for obj in self.all().values():
AttributeError: 'DBStorage' object has no attribute 'all'
2024-07-07 17:48:17 ERROR OSError: write error
2024-07-07 17:48:18 ERROR Exception on /auth/login [GET]
Traceback (most recent call last):
  File "/home/Flasheeta/.virtualenvs/myenv/lib/python3.8/site-packages/flask/app.py", line 1473, in wsgi_app
    response = self.full_dispatch_request()
  File "/home/Flasheeta/.virtualenvs/myenv/lib/python3.8/site-packages/flask/app.py", line 882, in full_dispatch_request
    rv = self.handle_user_exception(e)
  File "/home/Flasheeta/.virtualenvs/myenv/lib/python3.8/site-packages/flask/app.py", line 880, in full_dispatch_request
    rv = self.dispatch_request()
  File "/home/Flasheeta/.virtualenvs/myenv/lib/python3.8/site-packages/flask/app.py", line 865, in dispatch_request
    return self.ensure_sync(self.view_functions[rule.endpoint])(**view_args)  # type: ignore[no-any-return]
  File "/home/Flasheeta/Flasheeta/app/web_routes/auth_routes.py", line 62, in login
    return render_template('login.html', form=form)
  File "/home/Flasheeta/.virtualenvs/myenv/lib/python3.8/site-packages/flask/templating.py", line 150, in render_template
    return _render(app, template, context)
  File "/home/Flasheeta/.virtualenvs/myenv/lib/python3.8/site-packages/flask/templating.py", line 127, in _render
    app.update_template_context(context)
  File "/home/Flasheeta/.virtualenvs/myenv/lib/python3.8/site-packages/flask/app.py", line 493, in update_template_context
    context.update(self.ensure_sync(func)())
  File "/home/Flasheeta/.virtualenvs/myenv/lib/python3.8/site-packages/flask_login/utils.py", line 405, in _user_context_processor
    return dict(current_user=_get_user())
  File "/home/Flasheeta/.virtualenvs/myenv/lib/python3.8/site-packages/flask_login/utils.py", line 370, in _get_user
    current_app.login_manager._load_user()
  File "/home/Flasheeta/.virtualenvs/myenv/lib/python3.8/site-packages/flask_login/login_manager.py", line 364, in _load_user
    user = self._user_callback(user_id)
  File "/home/Flasheeta/Flasheeta/app/__init__.py", line 54, in load_user
    return app.storage.get(User, user_id)
  File "/home/Flasheeta/Flasheeta/app/models/engine/db_storage.py", line 109, in get
    for obj in self.all().values():
AttributeError: 'DBStorage' object has no attribute 'all'
2024-07-07 17:48:20 ERROR Exception on /auth/login [GET]
Traceback (most recent call last):
  File "/home/Flasheeta/.virtualenvs/myenv/lib/python3.8/site-packages/flask/app.py", line 1473, in wsgi_app
    response = self.full_dispatch_request()
  File "/home/Flasheeta/.virtualenvs/myenv/lib/python3.8/site-packages/flask/app.py", line 882, in full_dispatch_request
    rv = self.handle_user_exception(e)
  File "/home/Flasheeta/.virtualenvs/myenv/lib/python3.8/site-packages/flask/app.py", line 880, in full_dispatch_request
    rv = self.dispatch_request()
  File "/home/Flasheeta/.virtualenvs/myenv/lib/python3.8/site-packages/flask/app.py", line 865, in dispatch_request
    return self.ensure_sync(self.view_functions[rule.endpoint])(**view_args)  # type: ignore[no-any-return]
  File "/home/Flasheeta/Flasheeta/app/web_routes/auth_routes.py", line 62, in login
    return render_template('login.html', form=form)
  File "/home/Flasheeta/.virtualenvs/myenv/lib/python3.8/site-packages/flask/templating.py", line 150, in render_template
    return _render(app, template, context)
  File "/home/Flasheeta/.virtualenvs/myenv/lib/python3.8/site-packages/flask/templating.py", line 127, in _render
    app.update_template_context(context)
  File "/home/Flasheeta/.virtualenvs/myenv/lib/python3.8/site-packages/flask/app.py", line 493, in update_template_context
    context.update(self.ensure_sync(func)())
  File "/home/Flasheeta/.virtualenvs/myenv/lib/python3.8/site-packages/flask_login/utils.py", line 405, in _user_context_processor
    return dict(current_user=_get_user())
  File "/home/Flasheeta/.virtualenvs/myenv/lib/python3.8/site-packages/flask_login/utils.py", line 370, in _get_user
    current_app.login_manager._load_user()
  File "/home/Flasheeta/.virtualenvs/myenv/lib/python3.8/site-packages/flask_login/login_manager.py", line 364, in _load_user
    user = self._user_callback(user_id)
  File "/home/Flasheeta/Flasheeta/app/__init__.py", line 54, in load_user
    return app.storage.get(User, user_id)
  File "/home/Flasheeta/Flasheeta/app/models/engine/db_storage.py", line 109, in get
    for obj in self.all().values():
AttributeError: 'DBStorage' object has no attribute 'all'
2024-07-07 17:48:47 ERROR Exception on /users/me/decks [GET]
Traceback (most recent call last):
  File "/home/Flasheeta/.virtualenvs/myenv/lib/python3.8/site-packages/flask/app.py", line 1473, in wsgi_app
    response = self.full_dispatch_request()
  File "/home/Flasheeta/.virtualenvs/myenv/lib/python3.8/site-packages/flask/app.py", line 882, in full_dispatch_request
    rv = self.handle_user_exception(e)
  File "/home/Flasheeta/.virtualenvs/myenv/lib/python3.8/site-packages/flask/app.py", line 880, in full_dispatch_request
    rv = self.dispatch_request()
  File "/home/Flasheeta/.virtualenvs/myenv/lib/python3.8/site-packages/flask/app.py", line 865, in dispatch_request
    return self.ensure_sync(self.view_functions[rule.endpoint])(**view_args)  # type: ignore[no-any-return]
  File "/home/Flasheeta/.virtualenvs/myenv/lib/python3.8/site-packages/flask_login/utils.py", line 284, in decorated_view
    elif not current_user.is_authenticated:
  File "/home/Flasheeta/.virtualenvs/myenv/lib/python3.8/site-packages/werkzeug/local.py", line 318, in __get__
    obj = instance._get_current_object()
  File "/home/Flasheeta/.virtualenvs/myenv/lib/python3.8/site-packages/werkzeug/local.py", line 526, in _get_current_object
    return get_name(local())
  File "/home/Flasheeta/.virtualenvs/myenv/lib/python3.8/site-packages/flask_login/utils.py", line 25, in <lambda>
    current_user = LocalProxy(lambda: _get_user())
  File "/home/Flasheeta/.virtualenvs/myenv/lib/python3.8/site-packages/flask_login/utils.py", line 370, in _get_user
    current_app.login_manager._load_user()
  File "/home/Flasheeta/.virtualenvs/myenv/lib/python3.8/site-packages/flask_login/login_manager.py", line 364, in _load_user
    user = self._user_callback(user_id)
  File "/home/Flasheeta/Flasheeta/app/__init__.py", line 54, in load_user
    return app.storage.get(User, user_id)
  File "/home/Flasheeta/Flasheeta/app/models/engine/db_storage.py", line 109, in get
    for obj in self.all().values():
AttributeError: 'DBStorage' object has no attribute 'all'
2024-07-07 17:48:49 ERROR Exception on /users/me/decks [GET]
Traceback (most recent call last):
  File "/home/Flasheeta/.virtualenvs/myenv/lib/python3.8/site-packages/flask/app.py", line 1473, in wsgi_app
    response = self.full_dispatch_request()
  File "/home/Flasheeta/.virtualenvs/myenv/lib/python3.8/site-packages/flask/app.py", line 882, in full_dispatch_request
    rv = self.handle_user_exception(e)
  File "/home/Flasheeta/.virtualenvs/myenv/lib/python3.8/site-packages/flask/app.py", line 880, in full_dispatch_request
    rv = self.dispatch_request()
  File "/home/Flasheeta/.virtualenvs/myenv/lib/python3.8/site-packages/flask/app.py", line 865, in dispatch_request
    return self.ensure_sync(self.view_functions[rule.endpoint])(**view_args)  # type: ignore[no-any-return]
  File "/home/Flasheeta/.virtualenvs/myenv/lib/python3.8/site-packages/flask_login/utils.py", line 284, in decorated_view
    elif not current_user.is_authenticated:
  File "/home/Flasheeta/.virtualenvs/myenv/lib/python3.8/site-packages/werkzeug/local.py", line 318, in __get__
    obj = instance._get_current_object()
  File "/home/Flasheeta/.virtualenvs/myenv/lib/python3.8/site-packages/werkzeug/local.py", line 526, in _get_current_object
    return get_name(local())
  File "/home/Flasheeta/.virtualenvs/myenv/lib/python3.8/site-packages/flask_login/utils.py", line 25, in <lambda>
    current_user = LocalProxy(lambda: _get_user())
  File "/home/Flasheeta/.virtualenvs/myenv/lib/python3.8/site-packages/flask_login/utils.py", line 370, in _get_user
    current_app.login_manager._load_user()
  File "/home/Flasheeta/.virtualenvs/myenv/lib/python3.8/site-packages/flask_login/login_manager.py", line 364, in _load_user
    user = self._user_callback(user_id)
  File "/home/Flasheeta/Flasheeta/app/__init__.py", line 54, in load_user
    return app.storage.get(User, user_id)
  File "/home/Flasheeta/Flasheeta/app/models/engine/db_storage.py", line 109, in get
    for obj in self.all().values():
AttributeError: 'DBStorage' object has no attribute 'all'
2024-07-07 17:52:06 ERROR Exception on /auth/login [GET]
Traceback (most recent call last):
  File "/home/Flasheeta/.virtualenvs/myenv/lib/python3.8/site-packages/flask/app.py", line 1473, in wsgi_app
    response = self.full_dispatch_request()
  File "/home/Flasheeta/.virtualenvs/myenv/lib/python3.8/site-packages/flask/app.py", line 882, in full_dispatch_request
    rv = self.handle_user_exception(e)
  File "/home/Flasheeta/.virtualenvs/myenv/lib/python3.8/site-packages/flask/app.py", line 880, in full_dispatch_request
    rv = self.dispatch_request()
  File "/home/Flasheeta/.virtualenvs/myenv/lib/python3.8/site-packages/flask/app.py", line 865, in dispatch_request
    return self.ensure_sync(self.view_functions[rule.endpoint])(**view_args)  # type: ignore[no-any-return]
  File "/home/Flasheeta/Flasheeta/app/web_routes/auth_routes.py", line 62, in login
    return render_template('login.html', form=form)
  File "/home/Flasheeta/.virtualenvs/myenv/lib/python3.8/site-packages/flask/templating.py", line 150, in render_template
    return _render(app, template, context)
  File "/home/Flasheeta/.virtualenvs/myenv/lib/python3.8/site-packages/flask/templating.py", line 127, in _render
    app.update_template_context(context)
  File "/home/Flasheeta/.virtualenvs/myenv/lib/python3.8/site-packages/flask/app.py", line 493, in update_template_context
    context.update(self.ensure_sync(func)())
  File "/home/Flasheeta/.virtualenvs/myenv/lib/python3.8/site-packages/flask_login/utils.py", line 405, in _user_context_processor
    return dict(current_user=_get_user())
  File "/home/Flasheeta/.virtualenvs/myenv/lib/python3.8/site-packages/flask_login/utils.py", line 370, in _get_user
    current_app.login_manager._load_user()
  File "/home/Flasheeta/.virtualenvs/myenv/lib/python3.8/site-packages/flask_login/login_manager.py", line 364, in _load_user
    user = self._user_callback(user_id)
  File "/home/Flasheeta/Flasheeta/app/__init__.py", line 54, in load_user
    return app.storage.get(User, user_id)
  File "/home/Flasheeta/Flasheeta/app/models/engine/db_storage.py", line 109, in get
    for obj in self.all().values():
AttributeError: 'DBStorage' object has no attribute 'all'
2024-07-07 17:53:09 ERROR Exception on /users/me/decks [GET]
Traceback (most recent call last):
  File "/home/Flasheeta/.virtualenvs/myenv/lib/python3.8/site-packages/flask/app.py", line 1473, in wsgi_app
    response = self.full_dispatch_request()
  File "/home/Flasheeta/.virtualenvs/myenv/lib/python3.8/site-packages/flask/app.py", line 882, in full_dispatch_request
    rv = self.handle_user_exception(e)
  File "/home/Flasheeta/.virtualenvs/myenv/lib/python3.8/site-packages/flask/app.py", line 880, in full_dispatch_request
    rv = self.dispatch_request()
  File "/home/Flasheeta/.virtualenvs/myenv/lib/python3.8/site-packages/flask/app.py", line 865, in dispatch_request
    return self.ensure_sync(self.view_functions[rule.endpoint])(**view_args)  # type: ignore[no-any-return]
  File "/home/Flasheeta/.virtualenvs/myenv/lib/python3.8/site-packages/flask_login/utils.py", line 284, in decorated_view
    elif not current_user.is_authenticated:
  File "/home/Flasheeta/.virtualenvs/myenv/lib/python3.8/site-packages/werkzeug/local.py", line 318, in __get__
    obj = instance._get_current_object()
  File "/home/Flasheeta/.virtualenvs/myenv/lib/python3.8/site-packages/werkzeug/local.py", line 526, in _get_current_object
    return get_name(local())
  File "/home/Flasheeta/.virtualenvs/myenv/lib/python3.8/site-packages/flask_login/utils.py", line 25, in <lambda>
    current_user = LocalProxy(lambda: _get_user())
  File "/home/Flasheeta/.virtualenvs/myenv/lib/python3.8/site-packages/flask_login/utils.py", line 370, in _get_user
    current_app.login_manager._load_user()
  File "/home/Flasheeta/.virtualenvs/myenv/lib/python3.8/site-packages/flask_login/login_manager.py", line 364, in _load_user
    user = self._user_callback(user_id)
  File "/home/Flasheeta/Flasheeta/app/__init__.py", line 54, in load_user
    return app.storage.get(User, user_id)
  File "/home/Flasheeta/Flasheeta/app/models/engine/db_storage.py", line 109, in get
    for obj in self.all().values():
AttributeError: 'DBStorage' object has no attribute 'all'
2024-07-07 17:53:13 ERROR Exception on /auth/login [GET]
Traceback (most recent call last):
  File "/home/Flasheeta/.virtualenvs/myenv/lib/python3.8/site-packages/flask/app.py", line 1473, in wsgi_app
    response = self.full_dispatch_request()
  File "/home/Flasheeta/.virtualenvs/myenv/lib/python3.8/site-packages/flask/app.py", line 882, in full_dispatch_request
    rv = self.handle_user_exception(e)
  File "/home/Flasheeta/.virtualenvs/myenv/lib/python3.8/site-packages/flask/app.py", line 880, in full_dispatch_request
    rv = self.dispatch_request()
  File "/home/Flasheeta/.virtualenvs/myenv/lib/python3.8/site-packages/flask/app.py", line 865, in dispatch_request
    return self.ensure_sync(self.view_functions[rule.endpoint])(**view_args)  # type: ignore[no-any-return]
  File "/home/Flasheeta/Flasheeta/app/web_routes/auth_routes.py", line 62, in login
    return render_template('login.html', form=form)
  File "/home/Flasheeta/.virtualenvs/myenv/lib/python3.8/site-packages/flask/templating.py", line 150, in render_template
    return _render(app, template, context)
  File "/home/Flasheeta/.virtualenvs/myenv/lib/python3.8/site-packages/flask/templating.py", line 127, in _render
    app.update_template_context(context)
  File "/home/Flasheeta/.virtualenvs/myenv/lib/python3.8/site-packages/flask/app.py", line 493, in update_template_context
    context.update(self.ensure_sync(func)())
  File "/home/Flasheeta/.virtualenvs/myenv/lib/python3.8/site-packages/flask_login/utils.py", line 405, in _user_context_processor
    return dict(current_user=_get_user())
  File "/home/Flasheeta/.virtualenvs/myenv/lib/python3.8/site-packages/flask_login/utils.py", line 370, in _get_user
    current_app.login_manager._load_user()
  File "/home/Flasheeta/.virtualenvs/myenv/lib/python3.8/site-packages/flask_login/login_manager.py", line 364, in _load_user
    user = self._user_callback(user_id)
  File "/home/Flasheeta/Flasheeta/app/__init__.py", line 54, in load_user
    return app.storage.get(User, user_id)
  File "/home/Flasheeta/Flasheeta/app/models/engine/db_storage.py", line 109, in get
    for obj in self.all().values():
AttributeError: 'DBStorage' object has no attribute 'all'
2024-07-07 17:55:52 ERROR Exception on /auth/login [GET]
Traceback (most recent call last):
  File "/home/Flasheeta/.virtualenvs/myenv/lib/python3.8/site-packages/flask/app.py", line 1473, in wsgi_app
    response = self.full_dispatch_request()
  File "/home/Flasheeta/.virtualenvs/myenv/lib/python3.8/site-packages/flask/app.py", line 882, in full_dispatch_request
    rv = self.handle_user_exception(e)
  File "/home/Flasheeta/.virtualenvs/myenv/lib/python3.8/site-packages/flask/app.py", line 880, in full_dispatch_request
    rv = self.dispatch_request()
  File "/home/Flasheeta/.virtualenvs/myenv/lib/python3.8/site-packages/flask/app.py", line 865, in dispatch_request
    return self.ensure_sync(self.view_functions[rule.endpoint])(**view_args)  # type: ignore[no-any-return]
  File "/home/Flasheeta/Flasheeta/app/web_routes/auth_routes.py", line 62, in login
    return render_template('login.html', form=form)
  File "/home/Flasheeta/.virtualenvs/myenv/lib/python3.8/site-packages/flask/templating.py", line 150, in render_template
    return _render(app, template, context)
  File "/home/Flasheeta/.virtualenvs/myenv/lib/python3.8/site-packages/flask/templating.py", line 127, in _render
    app.update_template_context(context)
  File "/home/Flasheeta/.virtualenvs/myenv/lib/python3.8/site-packages/flask/app.py", line 493, in update_template_context
    context.update(self.ensure_sync(func)())
  File "/home/Flasheeta/.virtualenvs/myenv/lib/python3.8/site-packages/flask_login/utils.py", line 405, in _user_context_processor
    return dict(current_user=_get_user())
  File "/home/Flasheeta/.virtualenvs/myenv/lib/python3.8/site-packages/flask_login/utils.py", line 370, in _get_user
    current_app.login_manager._load_user()
  File "/home/Flasheeta/.virtualenvs/myenv/lib/python3.8/site-packages/flask_login/login_manager.py", line 364, in _load_user
    user = self._user_callback(user_id)
  File "/home/Flasheeta/Flasheeta/app/__init__.py", line 54, in load_user
    return app.storage.get(User, user_id)
  File "/home/Flasheeta/Flasheeta/app/models/engine/db_storage.py", line 109, in get
    for obj in self.all().values():
AttributeError: 'DBStorage' object has no attribute 'all'
2024-07-07 17:55:55 ERROR Exception on /auth/login [GET]
Traceback (most recent call last):
  File "/home/Flasheeta/.virtualenvs/myenv/lib/python3.8/site-packages/flask/app.py", line 1473, in wsgi_app
    response = self.full_dispatch_request()
  File "/home/Flasheeta/.virtualenvs/myenv/lib/python3.8/site-packages/flask/app.py", line 882, in full_dispatch_request
    rv = self.handle_user_exception(e)
  File "/home/Flasheeta/.virtualenvs/myenv/lib/python3.8/site-packages/flask/app.py", line 880, in full_dispatch_request
    rv = self.dispatch_request()
  File "/home/Flasheeta/.virtualenvs/myenv/lib/python3.8/site-packages/flask/app.py", line 865, in dispatch_request
    return self.ensure_sync(self.view_functions[rule.endpoint])(**view_args)  # type: ignore[no-any-return]
  File "/home/Flasheeta/Flasheeta/app/web_routes/auth_routes.py", line 62, in login
    return render_template('login.html', form=form)
  File "/home/Flasheeta/.virtualenvs/myenv/lib/python3.8/site-packages/flask/templating.py", line 150, in render_template
    return _render(app, template, context)
  File "/home/Flasheeta/.virtualenvs/myenv/lib/python3.8/site-packages/flask/templating.py", line 127, in _render
    app.update_template_context(context)
  File "/home/Flasheeta/.virtualenvs/myenv/lib/python3.8/site-packages/flask/app.py", line 493, in update_template_context
    context.update(self.ensure_sync(func)())
  File "/home/Flasheeta/.virtualenvs/myenv/lib/python3.8/site-packages/flask_login/utils.py", line 405, in _user_context_processor
    return dict(current_user=_get_user())
  File "/home/Flasheeta/.virtualenvs/myenv/lib/python3.8/site-packages/flask_login/utils.py", line 370, in _get_user
    current_app.login_manager._load_user()
  File "/home/Flasheeta/.virtualenvs/myenv/lib/python3.8/site-packages/flask_login/login_manager.py", line 364, in _load_user
    user = self._user_callback(user_id)
  File "/home/Flasheeta/Flasheeta/app/__init__.py", line 54, in load_user
    return app.storage.get(User, user_id)
  File "/home/Flasheeta/Flasheeta/app/models/engine/db_storage.py", line 109, in get
    for obj in self.all().values():
AttributeError: 'DBStorage' object has no attribute 'all'
2024-07-07 17:56:24 ERROR Exception on /auth/login [GET]
Traceback (most recent call last):
  File "/home/Flasheeta/.virtualenvs/myenv/lib/python3.8/site-packages/flask/app.py", line 1473, in wsgi_app
    response = self.full_dispatch_request()
  File "/home/Flasheeta/.virtualenvs/myenv/lib/python3.8/site-packages/flask/app.py", line 882, in full_dispatch_request
    rv = self.handle_user_exception(e)
  File "/home/Flasheeta/.virtualenvs/myenv/lib/python3.8/site-packages/flask/app.py", line 880, in full_dispatch_request
    rv = self.dispatch_request()
  File "/home/Flasheeta/.virtualenvs/myenv/lib/python3.8/site-packages/flask/app.py", line 865, in dispatch_request
    return self.ensure_sync(self.view_functions[rule.endpoint])(**view_args)  # type: ignore[no-any-return]
  File "/home/Flasheeta/Flasheeta/app/web_routes/auth_routes.py", line 62, in login
    return render_template('login.html', form=form)
  File "/home/Flasheeta/.virtualenvs/myenv/lib/python3.8/site-packages/flask/templating.py", line 150, in render_template
    return _render(app, template, context)
  File "/home/Flasheeta/.virtualenvs/myenv/lib/python3.8/site-packages/flask/templating.py", line 127, in _render
    app.update_template_context(context)
  File "/home/Flasheeta/.virtualenvs/myenv/lib/python3.8/site-packages/flask/app.py", line 493, in update_template_context
    context.update(self.ensure_sync(func)())
  File "/home/Flasheeta/.virtualenvs/myenv/lib/python3.8/site-packages/flask_login/utils.py", line 405, in _user_context_processor
    return dict(current_user=_get_user())
  File "/home/Flasheeta/.virtualenvs/myenv/lib/python3.8/site-packages/flask_login/utils.py", line 370, in _get_user
    current_app.login_manager._load_user()
  File "/home/Flasheeta/.virtualenvs/myenv/lib/python3.8/site-packages/flask_login/login_manager.py", line 364, in _load_user
    user = self._user_callback(user_id)
  File "/home/Flasheeta/Flasheeta/app/__init__.py", line 54, in load_user
    return app.storage.get(User, user_id)
  File "/home/Flasheeta/Flasheeta/app/models/engine/db_storage.py", line 109, in get
    for obj in self.all().values():
AttributeError: 'DBStorage' object has no attribute 'all'
2024-07-07 17:56:35 ERROR Exception on /auth/login [GET]
Traceback (most recent call last):
  File "/home/Flasheeta/.virtualenvs/myenv/lib/python3.8/site-packages/flask/app.py", line 1473, in wsgi_app
    response = self.full_dispatch_request()
  File "/home/Flasheeta/.virtualenvs/myenv/lib/python3.8/site-packages/flask/app.py", line 882, in full_dispatch_request
    rv = self.handle_user_exception(e)
  File "/home/Flasheeta/.virtualenvs/myenv/lib/python3.8/site-packages/flask/app.py", line 880, in full_dispatch_request
    rv = self.dispatch_request()
  File "/home/Flasheeta/.virtualenvs/myenv/lib/python3.8/site-packages/flask/app.py", line 865, in dispatch_request
    return self.ensure_sync(self.view_functions[rule.endpoint])(**view_args)  # type: ignore[no-any-return]
  File "/home/Flasheeta/Flasheeta/app/web_routes/auth_routes.py", line 62, in login
    return render_template('login.html', form=form)
  File "/home/Flasheeta/.virtualenvs/myenv/lib/python3.8/site-packages/flask/templating.py", line 150, in render_template
    return _render(app, template, context)
  File "/home/Flasheeta/.virtualenvs/myenv/lib/python3.8/site-packages/flask/templating.py", line 127, in _render
    app.update_template_context(context)
  File "/home/Flasheeta/.virtualenvs/myenv/lib/python3.8/site-packages/flask/app.py", line 493, in update_template_context
    context.update(self.ensure_sync(func)())
  File "/home/Flasheeta/.virtualenvs/myenv/lib/python3.8/site-packages/flask_login/utils.py", line 405, in _user_context_processor
    return dict(current_user=_get_user())
  File "/home/Flasheeta/.virtualenvs/myenv/lib/python3.8/site-packages/flask_login/utils.py", line 370, in _get_user
    current_app.login_manager._load_user()
  File "/home/Flasheeta/.virtualenvs/myenv/lib/python3.8/site-packages/flask_login/login_manager.py", line 364, in _load_user
    user = self._user_callback(user_id)
  File "/home/Flasheeta/Flasheeta/app/__init__.py", line 54, in load_user
    return app.storage.get(User, user_id)
  File "/home/Flasheeta/Flasheeta/app/models/engine/db_storage.py", line 109, in get
    for obj in self.all().values():
AttributeError: 'DBStorage' object has no attribute 'all'
2024-07-07 17:56:37 ERROR Exception on /auth/login [GET]
Traceback (most recent call last):
  File "/home/Flasheeta/.virtualenvs/myenv/lib/python3.8/site-packages/flask/app.py", line 1473, in wsgi_app
    response = self.full_dispatch_request()
  File "/home/Flasheeta/.virtualenvs/myenv/lib/python3.8/site-packages/flask/app.py", line 882, in full_dispatch_request
    rv = self.handle_user_exception(e)
  File "/home/Flasheeta/.virtualenvs/myenv/lib/python3.8/site-packages/flask/app.py", line 880, in full_dispatch_request
    rv = self.dispatch_request()
  File "/home/Flasheeta/.virtualenvs/myenv/lib/python3.8/site-packages/flask/app.py", line 865, in dispatch_request
    return self.ensure_sync(self.view_functions[rule.endpoint])(**view_args)  # type: ignore[no-any-return]
  File "/home/Flasheeta/Flasheeta/app/web_routes/auth_routes.py", line 62, in login
    return render_template('login.html', form=form)
  File "/home/Flasheeta/.virtualenvs/myenv/lib/python3.8/site-packages/flask/templating.py", line 150, in render_template
    return _render(app, template, context)
  File "/home/Flasheeta/.virtualenvs/myenv/lib/python3.8/site-packages/flask/templating.py", line 127, in _render
    app.update_template_context(context)
  File "/home/Flasheeta/.virtualenvs/myenv/lib/python3.8/site-packages/flask/app.py", line 493, in update_template_context
    context.update(self.ensure_sync(func)())
  File "/home/Flasheeta/.virtualenvs/myenv/lib/python3.8/site-packages/flask_login/utils.py", line 405, in _user_context_processor
    return dict(current_user=_get_user())
  File "/home/Flasheeta/.virtualenvs/myenv/lib/python3.8/site-packages/flask_login/utils.py", line 370, in _get_user
    current_app.login_manager._load_user()
  File "/home/Flasheeta/.virtualenvs/myenv/lib/python3.8/site-packages/flask_login/login_manager.py", line 364, in _load_user
    user = self._user_callback(user_id)
  File "/home/Flasheeta/Flasheeta/app/__init__.py", line 54, in load_user
    return app.storage.get(User, user_id)
  File "/home/Flasheeta/Flasheeta/app/models/engine/db_storage.py", line 109, in get
    for obj in self.all().values():
AttributeError: 'DBStorage' object has no attribute 'all'
2024-07-07 17:57:01 ERROR Exception on /users/me/decks [GET]
Traceback (most recent call last):
  File "/home/Flasheeta/.virtualenvs/myenv/lib/python3.8/site-packages/flask/app.py", line 1473, in wsgi_app
    response = self.full_dispatch_request()
  File "/home/Flasheeta/.virtualenvs/myenv/lib/python3.8/site-packages/flask/app.py", line 882, in full_dispatch_request
    rv = self.handle_user_exception(e)
  File "/home/Flasheeta/.virtualenvs/myenv/lib/python3.8/site-packages/flask/app.py", line 880, in full_dispatch_request
    rv = self.dispatch_request()
  File "/home/Flasheeta/.virtualenvs/myenv/lib/python3.8/site-packages/flask/app.py", line 865, in dispatch_request
    return self.ensure_sync(self.view_functions[rule.endpoint])(**view_args)  # type: ignore[no-any-return]
  File "/home/Flasheeta/.virtualenvs/myenv/lib/python3.8/site-packages/flask_login/utils.py", line 284, in decorated_view
    elif not current_user.is_authenticated:
  File "/home/Flasheeta/.virtualenvs/myenv/lib/python3.8/site-packages/werkzeug/local.py", line 318, in __get__
    obj = instance._get_current_object()
  File "/home/Flasheeta/.virtualenvs/myenv/lib/python3.8/site-packages/werkzeug/local.py", line 526, in _get_current_object
    return get_name(local())
  File "/home/Flasheeta/.virtualenvs/myenv/lib/python3.8/site-packages/flask_login/utils.py", line 25, in <lambda>
    current_user = LocalProxy(lambda: _get_user())
  File "/home/Flasheeta/.virtualenvs/myenv/lib/python3.8/site-packages/flask_login/utils.py", line 370, in _get_user
    current_app.login_manager._load_user()
  File "/home/Flasheeta/.virtualenvs/myenv/lib/python3.8/site-packages/flask_login/login_manager.py", line 364, in _load_user
    user = self._user_callback(user_id)
  File "/home/Flasheeta/Flasheeta/app/__init__.py", line 54, in load_user
    return app.storage.get(User, user_id)
  File "/home/Flasheeta/Flasheeta/app/models/engine/db_storage.py", line 109, in get
    for obj in self.all().values():
AttributeError: 'DBStorage' object has no attribute 'all'
2024-07-07 17:58:36 ERROR Exception on /auth/login [GET]
Traceback (most recent call last):
  File "/home/Flasheeta/.virtualenvs/myenv/lib/python3.8/site-packages/flask/app.py", line 1473, in wsgi_app
    response = self.full_dispatch_request()
  File "/home/Flasheeta/.virtualenvs/myenv/lib/python3.8/site-packages/flask/app.py", line 882, in full_dispatch_request
    rv = self.handle_user_exception(e)
  File "/home/Flasheeta/.virtualenvs/myenv/lib/python3.8/site-packages/flask/app.py", line 880, in full_dispatch_request
    rv = self.dispatch_request()
  File "/home/Flasheeta/.virtualenvs/myenv/lib/python3.8/site-packages/flask/app.py", line 865, in dispatch_request
    return self.ensure_sync(self.view_functions[rule.endpoint])(**view_args)  # type: ignore[no-any-return]
  File "/home/Flasheeta/Flasheeta/app/web_routes/auth_routes.py", line 62, in login
    return render_template('login.html', form=form)
  File "/home/Flasheeta/.virtualenvs/myenv/lib/python3.8/site-packages/flask/templating.py", line 150, in render_template
    return _render(app, template, context)
  File "/home/Flasheeta/.virtualenvs/myenv/lib/python3.8/site-packages/flask/templating.py", line 127, in _render
    app.update_template_context(context)
  File "/home/Flasheeta/.virtualenvs/myenv/lib/python3.8/site-packages/flask/app.py", line 493, in update_template_context
    context.update(self.ensure_sync(func)())
  File "/home/Flasheeta/.virtualenvs/myenv/lib/python3.8/site-packages/flask_login/utils.py", line 405, in _user_context_processor
    return dict(current_user=_get_user())
  File "/home/Flasheeta/.virtualenvs/myenv/lib/python3.8/site-packages/flask_login/utils.py", line 370, in _get_user
    current_app.login_manager._load_user()
  File "/home/Flasheeta/.virtualenvs/myenv/lib/python3.8/site-packages/flask_login/login_manager.py", line 364, in _load_user
    user = self._user_callback(user_id)
  File "/home/Flasheeta/Flasheeta/app/__init__.py", line 54, in load_user
    return app.storage.get(User, user_id)
  File "/home/Flasheeta/Flasheeta/app/models/engine/db_storage.py", line 109, in get
    for obj in self.all().values():
AttributeError: 'DBStorage' object has no attribute 'all'
2024-07-07 17:58:44 ERROR Exception on /auth/login [GET]
Traceback (most recent call last):
  File "/home/Flasheeta/.virtualenvs/myenv/lib/python3.8/site-packages/flask/app.py", line 1473, in wsgi_app
    response = self.full_dispatch_request()
  File "/home/Flasheeta/.virtualenvs/myenv/lib/python3.8/site-packages/flask/app.py", line 882, in full_dispatch_request
    rv = self.handle_user_exception(e)
  File "/home/Flasheeta/.virtualenvs/myenv/lib/python3.8/site-packages/flask/app.py", line 880, in full_dispatch_request
    rv = self.dispatch_request()
  File "/home/Flasheeta/.virtualenvs/myenv/lib/python3.8/site-packages/flask/app.py", line 865, in dispatch_request
    return self.ensure_sync(self.view_functions[rule.endpoint])(**view_args)  # type: ignore[no-any-return]
  File "/home/Flasheeta/Flasheeta/app/web_routes/auth_routes.py", line 62, in login
    return render_template('login.html', form=form)
  File "/home/Flasheeta/.virtualenvs/myenv/lib/python3.8/site-packages/flask/templating.py", line 150, in render_template
    return _render(app, template, context)
  File "/home/Flasheeta/.virtualenvs/myenv/lib/python3.8/site-packages/flask/templating.py", line 127, in _render
    app.update_template_context(context)
  File "/home/Flasheeta/.virtualenvs/myenv/lib/python3.8/site-packages/flask/app.py", line 493, in update_template_context
    context.update(self.ensure_sync(func)())
  File "/home/Flasheeta/.virtualenvs/myenv/lib/python3.8/site-packages/flask_login/utils.py", line 405, in _user_context_processor
    return dict(current_user=_get_user())
  File "/home/Flasheeta/.virtualenvs/myenv/lib/python3.8/site-packages/flask_login/utils.py", line 370, in _get_user
    current_app.login_manager._load_user()
  File "/home/Flasheeta/.virtualenvs/myenv/lib/python3.8/site-packages/flask_login/login_manager.py", line 364, in _load_user
    user = self._user_callback(user_id)
  File "/home/Flasheeta/Flasheeta/app/__init__.py", line 54, in load_user
    return app.storage.get(User, user_id)
  File "/home/Flasheeta/Flasheeta/app/models/engine/db_storage.py", line 109, in get
    for obj in self.all().values():
AttributeError: 'DBStorage' object has no attribute 'all'
2024-07-07 18:05:00 ERROR Exception on /auth/login [GET]
Traceback (most recent call last):
  File "/home/Flasheeta/.virtualenvs/myenv/lib/python3.8/site-packages/flask/app.py", line 1473, in wsgi_app
    response = self.full_dispatch_request()
  File "/home/Flasheeta/.virtualenvs/myenv/lib/python3.8/site-packages/flask/app.py", line 882, in full_dispatch_request
    rv = self.handle_user_exception(e)
  File "/home/Flasheeta/.virtualenvs/myenv/lib/python3.8/site-packages/flask/app.py", line 880, in full_dispatch_request
    rv = self.dispatch_request()
  File "/home/Flasheeta/.virtualenvs/myenv/lib/python3.8/site-packages/flask/app.py", line 865, in dispatch_request
    return self.ensure_sync(self.view_functions[rule.endpoint])(**view_args)  # type: ignore[no-any-return]
  File "/home/Flasheeta/Flasheeta/app/web_routes/auth_routes.py", line 62, in login
    return render_template('login.html', form=form)
  File "/home/Flasheeta/.virtualenvs/myenv/lib/python3.8/site-packages/flask/templating.py", line 150, in render_template
    return _render(app, template, context)
  File "/home/Flasheeta/.virtualenvs/myenv/lib/python3.8/site-packages/flask/templating.py", line 127, in _render
    app.update_template_context(context)
  File "/home/Flasheeta/.virtualenvs/myenv/lib/python3.8/site-packages/flask/app.py", line 493, in update_template_context
    context.update(self.ensure_sync(func)())
  File "/home/Flasheeta/.virtualenvs/myenv/lib/python3.8/site-packages/flask_login/utils.py", line 405, in _user_context_processor
    return dict(current_user=_get_user())
  File "/home/Flasheeta/.virtualenvs/myenv/lib/python3.8/site-packages/flask_login/utils.py", line 370, in _get_user
    current_app.login_manager._load_user()
  File "/home/Flasheeta/.virtualenvs/myenv/lib/python3.8/site-packages/flask_login/login_manager.py", line 364, in _load_user
    user = self._user_callback(user_id)
  File "/home/Flasheeta/Flasheeta/app/__init__.py", line 54, in load_user
    return app.storage.get(User, user_id)
  File "/home/Flasheeta/Flasheeta/app/models/engine/db_storage.py", line 109, in get
    for obj in self.all().values():
AttributeError: 'DBStorage' object has no attribute 'all'
2024-07-07 18:21:16 ERROR Exception on /auth/login [GET]
Traceback (most recent call last):
  File "/home/Flasheeta/.virtualenvs/myenv/lib/python3.8/site-packages/flask/app.py", line 1473, in wsgi_app
    response = self.full_dispatch_request()
  File "/home/Flasheeta/.virtualenvs/myenv/lib/python3.8/site-packages/flask/app.py", line 882, in full_dispatch_request
    rv = self.handle_user_exception(e)
  File "/home/Flasheeta/.virtualenvs/myenv/lib/python3.8/site-packages/flask/app.py", line 880, in full_dispatch_request
    rv = self.dispatch_request()
  File "/home/Flasheeta/.virtualenvs/myenv/lib/python3.8/site-packages/flask/app.py", line 865, in dispatch_request
    return self.ensure_sync(self.view_functions[rule.endpoint])(**view_args)  # type: ignore[no-any-return]
  File "/home/Flasheeta/Flasheeta/app/web_routes/auth_routes.py", line 62, in login
    return render_template('login.html', form=form)
  File "/home/Flasheeta/.virtualenvs/myenv/lib/python3.8/site-packages/flask/templating.py", line 150, in render_template
    return _render(app, template, context)
  File "/home/Flasheeta/.virtualenvs/myenv/lib/python3.8/site-packages/flask/templating.py", line 127, in _render
    app.update_template_context(context)
  File "/home/Flasheeta/.virtualenvs/myenv/lib/python3.8/site-packages/flask/app.py", line 493, in update_template_context
    context.update(self.ensure_sync(func)())
  File "/home/Flasheeta/.virtualenvs/myenv/lib/python3.8/site-packages/flask_login/utils.py", line 405, in _user_context_processor
    return dict(current_user=_get_user())
  File "/home/Flasheeta/.virtualenvs/myenv/lib/python3.8/site-packages/flask_login/utils.py", line 370, in _get_user
    current_app.login_manager._load_user()
  File "/home/Flasheeta/.virtualenvs/myenv/lib/python3.8/site-packages/flask_login/login_manager.py", line 364, in _load_user
    user = self._user_callback(user_id)
  File "/home/Flasheeta/Flasheeta/app/__init__.py", line 54, in load_user
    return app.storage.get(User, user_id)
  File "/home/Flasheeta/Flasheeta/app/models/engine/db_storage.py", line 109, in get
    for obj in self.all().values():
AttributeError: 'DBStorage' object has no attribute 'all'
2024-07-07 18:21:45 ERROR Exception on /users/me/decks [GET]
Traceback (most recent call last):
  File "/home/Flasheeta/.virtualenvs/myenv/lib/python3.8/site-packages/flask/app.py", line 1473, in wsgi_app
    response = self.full_dispatch_request()
  File "/home/Flasheeta/.virtualenvs/myenv/lib/python3.8/site-packages/flask/app.py", line 882, in full_dispatch_request
    rv = self.handle_user_exception(e)
  File "/home/Flasheeta/.virtualenvs/myenv/lib/python3.8/site-packages/flask/app.py", line 880, in full_dispatch_request
    rv = self.dispatch_request()
  File "/home/Flasheeta/.virtualenvs/myenv/lib/python3.8/site-packages/flask/app.py", line 865, in dispatch_request
    return self.ensure_sync(self.view_functions[rule.endpoint])(**view_args)  # type: ignore[no-any-return]
  File "/home/Flasheeta/.virtualenvs/myenv/lib/python3.8/site-packages/flask_login/utils.py", line 284, in decorated_view
    elif not current_user.is_authenticated:
  File "/home/Flasheeta/.virtualenvs/myenv/lib/python3.8/site-packages/werkzeug/local.py", line 318, in __get__
    obj = instance._get_current_object()
  File "/home/Flasheeta/.virtualenvs/myenv/lib/python3.8/site-packages/werkzeug/local.py", line 526, in _get_current_object
    return get_name(local())
  File "/home/Flasheeta/.virtualenvs/myenv/lib/python3.8/site-packages/flask_login/utils.py", line 25, in <lambda>
    current_user = LocalProxy(lambda: _get_user())
  File "/home/Flasheeta/.virtualenvs/myenv/lib/python3.8/site-packages/flask_login/utils.py", line 370, in _get_user
    current_app.login_manager._load_user()
  File "/home/Flasheeta/.virtualenvs/myenv/lib/python3.8/site-packages/flask_login/login_manager.py", line 364, in _load_user
    user = self._user_callback(user_id)
  File "/home/Flasheeta/Flasheeta/app/__init__.py", line 54, in load_user
    return app.storage.get(User, user_id)
  File "/home/Flasheeta/Flasheeta/app/models/engine/db_storage.py", line 109, in get
    for obj in self.all().values():
AttributeError: 'DBStorage' object has no attribute 'all'
2024-07-07 18:24:58 ERROR Exception on /auth/login [GET]
Traceback (most recent call last):
  File "/home/Flasheeta/.virtualenvs/myenv/lib/python3.8/site-packages/flask/app.py", line 1473, in wsgi_app
    response = self.full_dispatch_request()
  File "/home/Flasheeta/.virtualenvs/myenv/lib/python3.8/site-packages/flask/app.py", line 882, in full_dispatch_request
    rv = self.handle_user_exception(e)
  File "/home/Flasheeta/.virtualenvs/myenv/lib/python3.8/site-packages/flask/app.py", line 880, in full_dispatch_request
    rv = self.dispatch_request()
  File "/home/Flasheeta/.virtualenvs/myenv/lib/python3.8/site-packages/flask/app.py", line 865, in dispatch_request
    return self.ensure_sync(self.view_functions[rule.endpoint])(**view_args)  # type: ignore[no-any-return]
  File "/home/Flasheeta/Flasheeta/app/web_routes/auth_routes.py", line 62, in login
    return render_template('login.html', form=form)
  File "/home/Flasheeta/.virtualenvs/myenv/lib/python3.8/site-packages/flask/templating.py", line 150, in render_template
    return _render(app, template, context)
  File "/home/Flasheeta/.virtualenvs/myenv/lib/python3.8/site-packages/flask/templating.py", line 127, in _render
    app.update_template_context(context)
  File "/home/Flasheeta/.virtualenvs/myenv/lib/python3.8/site-packages/flask/app.py", line 493, in update_template_context
    context.update(self.ensure_sync(func)())
  File "/home/Flasheeta/.virtualenvs/myenv/lib/python3.8/site-packages/flask_login/utils.py", line 405, in _user_context_processor
    return dict(current_user=_get_user())
  File "/home/Flasheeta/.virtualenvs/myenv/lib/python3.8/site-packages/flask_login/utils.py", line 370, in _get_user
    current_app.login_manager._load_user()
  File "/home/Flasheeta/.virtualenvs/myenv/lib/python3.8/site-packages/flask_login/login_manager.py", line 364, in _load_user
    user = self._user_callback(user_id)
  File "/home/Flasheeta/Flasheeta/app/__init__.py", line 54, in load_user
    return app.storage.get(User, user_id)
  File "/home/Flasheeta/Flasheeta/app/models/engine/db_storage.py", line 109, in get
    for obj in self.all().values():
AttributeError: 'DBStorage' object has no attribute 'all'
2024-07-07 18:33:30 ERROR Exception on /api/v1/users/me/flashcards/bed72a50-ab04-499a-999b-64533e5f3b59/progress [PUT]
Traceback (most recent call last):
  File "/home/Flasheeta/.virtualenvs/myenv/lib/python3.8/site-packages/flask/app.py", line 1473, in wsgi_app
    response = self.full_dispatch_request()
  File "/home/Flasheeta/.virtualenvs/myenv/lib/python3.8/site-packages/flask/app.py", line 882, in full_dispatch_request
    rv = self.handle_user_exception(e)
  File "/home/Flasheeta/.virtualenvs/myenv/lib/python3.8/site-packages/flask/app.py", line 880, in full_dispatch_request
    rv = self.dispatch_request()
  File "/home/Flasheeta/.virtualenvs/myenv/lib/python3.8/site-packages/flask/app.py", line 865, in dispatch_request
    return self.ensure_sync(self.view_functions[rule.endpoint])(**view_args)  # type: ignore[no-any-return]
  File "/home/Flasheeta/.virtualenvs/myenv/lib/python3.8/site-packages/flask_login/utils.py", line 290, in decorated_view
    return current_app.ensure_sync(func)(*args, **kwargs)
  File "/home/Flasheeta/Flasheeta/app/api/v1/views/progress.py", line 76, in update_flashcard_progress
    return jsonify(progress.to_dict()), 200
  File "/home/Flasheeta/Flasheeta/app/models/base_model.py", line 52, in to_dict
    dct['created_at'] = dct.get('created_at').isoformat()
AttributeError: 'NoneType' object has no attribute 'isoformat'
2024-07-07 18:33:32 ERROR Exception on /api/v1/users/me/flashcards/bed72a50-ab04-499a-999b-64533e5f3b59/progress [PUT]
Traceback (most recent call last):
  File "/home/Flasheeta/.virtualenvs/myenv/lib/python3.8/site-packages/flask/app.py", line 1473, in wsgi_app
    response = self.full_dispatch_request()
  File "/home/Flasheeta/.virtualenvs/myenv/lib/python3.8/site-packages/flask/app.py", line 882, in full_dispatch_request
    rv = self.handle_user_exception(e)
  File "/home/Flasheeta/.virtualenvs/myenv/lib/python3.8/site-packages/flask/app.py", line 880, in full_dispatch_request
    rv = self.dispatch_request()
  File "/home/Flasheeta/.virtualenvs/myenv/lib/python3.8/site-packages/flask/app.py", line 865, in dispatch_request
    return self.ensure_sync(self.view_functions[rule.endpoint])(**view_args)  # type: ignore[no-any-return]
  File "/home/Flasheeta/.virtualenvs/myenv/lib/python3.8/site-packages/flask_login/utils.py", line 290, in decorated_view
    return current_app.ensure_sync(func)(*args, **kwargs)
  File "/home/Flasheeta/Flasheeta/app/api/v1/views/progress.py", line 76, in update_flashcard_progress
    return jsonify(progress.to_dict()), 200
  File "/home/Flasheeta/Flasheeta/app/models/base_model.py", line 52, in to_dict
    dct['created_at'] = dct.get('created_at').isoformat()
AttributeError: 'NoneType' object has no attribute 'isoformat'
2024-07-07 19:34:18 ERROR Exception on /api/v1/users/me/flashcards/18630840-5df8-4321-95d8-247db0cb220d/progress [PUT]
Traceback (most recent call last):
  File "/home/Flasheeta/.virtualenvs/myenv/lib/python3.8/site-packages/flask/app.py", line 1473, in wsgi_app
    response = self.full_dispatch_request()
  File "/home/Flasheeta/.virtualenvs/myenv/lib/python3.8/site-packages/flask/app.py", line 882, in full_dispatch_request
    rv = self.handle_user_exception(e)
  File "/home/Flasheeta/.virtualenvs/myenv/lib/python3.8/site-packages/flask/app.py", line 880, in full_dispatch_request
    rv = self.dispatch_request()
  File "/home/Flasheeta/.virtualenvs/myenv/lib/python3.8/site-packages/flask/app.py", line 865, in dispatch_request
    return self.ensure_sync(self.view_functions[rule.endpoint])(**view_args)  # type: ignore[no-any-return]
  File "/home/Flasheeta/.virtualenvs/myenv/lib/python3.8/site-packages/flask_login/utils.py", line 290, in decorated_view
    return current_app.ensure_sync(func)(*args, **kwargs)
  File "/home/Flasheeta/Flasheeta/app/api/v1/views/progress.py", line 99, in update_flashcard_progress
    return jsonify(progress.to_dict()), 200
  File "/home/Flasheeta/Flasheeta/app/models/base_model.py", line 52, in to_dict
    dct['created_at'] = dct.get('created_at').isoformat()
AttributeError: 'NoneType' object has no attribute 'isoformat'
2024-07-07 19:34:20 ERROR Exception on /api/v1/users/me/flashcards/781a5e14-36ed-49d0-b419-7e395edcc2f5/progress [PUT]
Traceback (most recent call last):
  File "/home/Flasheeta/.virtualenvs/myenv/lib/python3.8/site-packages/flask/app.py", line 1473, in wsgi_app
    response = self.full_dispatch_request()
  File "/home/Flasheeta/.virtualenvs/myenv/lib/python3.8/site-packages/flask/app.py", line 882, in full_dispatch_request
    rv = self.handle_user_exception(e)
  File "/home/Flasheeta/.virtualenvs/myenv/lib/python3.8/site-packages/flask/app.py", line 880, in full_dispatch_request
    rv = self.dispatch_request()
  File "/home/Flasheeta/.virtualenvs/myenv/lib/python3.8/site-packages/flask/app.py", line 865, in dispatch_request
    return self.ensure_sync(self.view_functions[rule.endpoint])(**view_args)  # type: ignore[no-any-return]
  File "/home/Flasheeta/.virtualenvs/myenv/lib/python3.8/site-packages/flask_login/utils.py", line 290, in decorated_view
    return current_app.ensure_sync(func)(*args, **kwargs)
  File "/home/Flasheeta/Flasheeta/app/api/v1/views/progress.py", line 99, in update_flashcard_progress
    return jsonify(progress.to_dict()), 200
  File "/home/Flasheeta/Flasheeta/app/models/base_model.py", line 52, in to_dict
    dct['created_at'] = dct.get('created_at').isoformat()
AttributeError: 'NoneType' object has no attribute 'isoformat'
2024-07-07 19:34:22 ERROR Exception on /api/v1/users/me/flashcards/781a5e14-36ed-49d0-b419-7e395edcc2f5/progress [PUT]
Traceback (most recent call last):
  File "/home/Flasheeta/.virtualenvs/myenv/lib/python3.8/site-packages/flask/app.py", line 1473, in wsgi_app
    response = self.full_dispatch_request()
  File "/home/Flasheeta/.virtualenvs/myenv/lib/python3.8/site-packages/flask/app.py", line 882, in full_dispatch_request
    rv = self.handle_user_exception(e)
  File "/home/Flasheeta/.virtualenvs/myenv/lib/python3.8/site-packages/flask/app.py", line 880, in full_dispatch_request
    rv = self.dispatch_request()
  File "/home/Flasheeta/.virtualenvs/myenv/lib/python3.8/site-packages/flask/app.py", line 865, in dispatch_request
    return self.ensure_sync(self.view_functions[rule.endpoint])(**view_args)  # type: ignore[no-any-return]
  File "/home/Flasheeta/.virtualenvs/myenv/lib/python3.8/site-packages/flask_login/utils.py", line 290, in decorated_view
    return current_app.ensure_sync(func)(*args, **kwargs)
  File "/home/Flasheeta/Flasheeta/app/api/v1/views/progress.py", line 99, in update_flashcard_progress
    return jsonify(progress.to_dict()), 200
  File "/home/Flasheeta/Flasheeta/app/models/base_model.py", line 52, in to_dict
    dct['created_at'] = dct.get('created_at').isoformat()
AttributeError: 'NoneType' object has no attribute 'isoformat'
2024-07-07 19:34:24 ERROR Exception on /api/v1/users/me/flashcards/781a5e14-36ed-49d0-b419-7e395edcc2f5/progress [PUT]
Traceback (most recent call last):
  File "/home/Flasheeta/.virtualenvs/myenv/lib/python3.8/site-packages/flask/app.py", line 1473, in wsgi_app
    response = self.full_dispatch_request()
  File "/home/Flasheeta/.virtualenvs/myenv/lib/python3.8/site-packages/flask/app.py", line 882, in full_dispatch_request
    rv = self.handle_user_exception(e)
  File "/home/Flasheeta/.virtualenvs/myenv/lib/python3.8/site-packages/flask/app.py", line 880, in full_dispatch_request
    rv = self.dispatch_request()
  File "/home/Flasheeta/.virtualenvs/myenv/lib/python3.8/site-packages/flask/app.py", line 865, in dispatch_request
    return self.ensure_sync(self.view_functions[rule.endpoint])(**view_args)  # type: ignore[no-any-return]
  File "/home/Flasheeta/.virtualenvs/myenv/lib/python3.8/site-packages/flask_login/utils.py", line 290, in decorated_view
    return current_app.ensure_sync(func)(*args, **kwargs)
  File "/home/Flasheeta/Flasheeta/app/api/v1/views/progress.py", line 99, in update_flashcard_progress
    return jsonify(progress.to_dict()), 200
  File "/home/Flasheeta/Flasheeta/app/models/base_model.py", line 52, in to_dict
    dct['created_at'] = dct.get('created_at').isoformat()
AttributeError: 'NoneType' object has no attribute 'isoformat'
2024-07-07 19:34:31 ERROR Exception on /api/v1/users/me/flashcards/18630840-5df8-4321-95d8-247db0cb220d/progress [PUT]
Traceback (most recent call last):
  File "/home/Flasheeta/.virtualenvs/myenv/lib/python3.8/site-packages/flask/app.py", line 1473, in wsgi_app
    response = self.full_dispatch_request()
  File "/home/Flasheeta/.virtualenvs/myenv/lib/python3.8/site-packages/flask/app.py", line 882, in full_dispatch_request
    rv = self.handle_user_exception(e)
  File "/home/Flasheeta/.virtualenvs/myenv/lib/python3.8/site-packages/flask/app.py", line 880, in full_dispatch_request
    rv = self.dispatch_request()
  File "/home/Flasheeta/.virtualenvs/myenv/lib/python3.8/site-packages/flask/app.py", line 865, in dispatch_request
    return self.ensure_sync(self.view_functions[rule.endpoint])(**view_args)  # type: ignore[no-any-return]
  File "/home/Flasheeta/.virtualenvs/myenv/lib/python3.8/site-packages/flask_login/utils.py", line 290, in decorated_view
    return current_app.ensure_sync(func)(*args, **kwargs)
  File "/home/Flasheeta/Flasheeta/app/api/v1/views/progress.py", line 99, in update_flashcard_progress
    return jsonify(progress.to_dict()), 200
  File "/home/Flasheeta/Flasheeta/app/models/base_model.py", line 52, in to_dict
    dct['created_at'] = dct.get('created_at').isoformat()
AttributeError: 'NoneType' object has no attribute 'isoformat'
2024-07-07 20:00:49 ERROR Exception on /api/v1/users/me/flashcards/18630840-5df8-4321-95d8-247db0cb220d/progress [PUT]
Traceback (most recent call last):
  File "/home/Flasheeta/.virtualenvs/myenv/lib/python3.8/site-packages/flask/app.py", line 1473, in wsgi_app
    response = self.full_dispatch_request()
  File "/home/Flasheeta/.virtualenvs/myenv/lib/python3.8/site-packages/flask/app.py", line 882, in full_dispatch_request
    rv = self.handle_user_exception(e)
  File "/home/Flasheeta/.virtualenvs/myenv/lib/python3.8/site-packages/flask/app.py", line 880, in full_dispatch_request
    rv = self.dispatch_request()
  File "/home/Flasheeta/.virtualenvs/myenv/lib/python3.8/site-packages/flask/app.py", line 865, in dispatch_request
    return self.ensure_sync(self.view_functions[rule.endpoint])(**view_args)  # type: ignore[no-any-return]
  File "/home/Flasheeta/.virtualenvs/myenv/lib/python3.8/site-packages/flask_login/utils.py", line 290, in decorated_view
    return current_app.ensure_sync(func)(*args, **kwargs)
  File "/home/Flasheeta/Flasheeta/app/api/v1/views/progress.py", line 99, in update_flashcard_progress
    return jsonify(progress.to_dict()), 200
  File "/home/Flasheeta/Flasheeta/app/models/base_model.py", line 52, in to_dict
    dct['created_at'] = dct.get('created_at').isoformat()
AttributeError: 'NoneType' object has no attribute 'isoformat'
2024-07-07 21:08:27 ERROR Exception on /api/v1/users/me/flashcards/faa8d316-d49c-46ca-baf0-3cfc1ffe8565/progress [PUT]
Traceback (most recent call last):
  File "/home/Flasheeta/.virtualenvs/myenv/lib/python3.8/site-packages/flask/app.py", line 1473, in wsgi_app
    response = self.full_dispatch_request()
  File "/home/Flasheeta/.virtualenvs/myenv/lib/python3.8/site-packages/flask/app.py", line 882, in full_dispatch_request
    rv = self.handle_user_exception(e)
  File "/home/Flasheeta/.virtualenvs/myenv/lib/python3.8/site-packages/flask/app.py", line 880, in full_dispatch_request
    rv = self.dispatch_request()
  File "/home/Flasheeta/.virtualenvs/myenv/lib/python3.8/site-packages/flask/app.py", line 865, in dispatch_request
    return self.ensure_sync(self.view_functions[rule.endpoint])(**view_args)  # type: ignore[no-any-return]
  File "/home/Flasheeta/.virtualenvs/myenv/lib/python3.8/site-packages/flask_login/utils.py", line 290, in decorated_view
    return current_app.ensure_sync(func)(*args, **kwargs)
  File "/home/Flasheeta/Flasheeta/app/api/v1/views/progress.py", line 99, in update_flashcard_progress
    return jsonify(progress.to_dict()), 200
  File "/home/Flasheeta/Flasheeta/app/models/base_model.py", line 52, in to_dict
    dct['created_at'] = dct.get('created_at').isoformat()
AttributeError: 'NoneType' object has no attribute 'isoformat'
